Workbook

Sheet 【1月】月間進捗管理シート
A1: 縞谷 | B1: 計画値 | D1: 現状 | E1: 土 | F1: 第1週 | G1: 月 | H1: 火 | I1: 水 | J1: 木 | K1: 金 | L1: 土 | M1: 第2週 | N1: 月 | O1: 火 | P1: 水 | Q1: 木 | R1: 金 | S1: 土 | T1: 第3週 | U1: 月 | V1: 火 | W1: 水 | X1: 木 | Y1: 金
E2: 45668 | F2: 45669 | G2: 45670 | H2: 45671 | I2: 45672 | J2: 45673 | K2: 45674 | L2: 45675 | M2: 45676 | N2: 45677 | O2: 45678 | P2: 45679 | Q2: 45680 | R2: 45681 | S2: 45682 | T2: 45683 | U2: 45684 | V2: 45685 | W2: 45686 | X2: 45687 | Y2: 45688
A3: 売上目標 | B3: 1000000 | C3: 現状売上 | D3: =sum(E3)+sum(G3:L3)+sum(N3:S3)+SUM(U3:Y3) -> 275000 | L3: 275000
A4: 目標受注数 | B4: 5 | C4: 現状受注数 | D4: =sum(E4)+sum(G4:L4)+sum(N4:S4)+SUM(U4:Y4) -> 1 | L4: 1
A5: 目標有効商談数 | B5: =B4/B11 -> 25 | C5: 現状有効商談数 | D5: =sum(E5)+sum(G5:L5)+sum(N5:S5)+SUM(U5:Y5) -> 5 | G5: 1 | H5: 1 | I5: 1 | L5: 1 | O5: 1
A6: 目標無効商談数 | C6: 現状無効商談数 | D6: =sum(E6)+sum(G6:L6)+sum(N6:S6)+SUM(U6:Y6) -> 0
C7: 商談予定 | D7: =sum(E7)+sum(G7:L7)+sum(N7:S7)+SUM(U7:Y7) -> 5 | G7: 1 | H7: 1 | I7: 1 | L7: 1 | O7: 1
C8: 当日アポ目標 | D8: =sum(E8)+sum(G8:L8)+sum(N8:S8)+SUM(U8:Y8) -> 0
A9: 目標アポ数 | B9: =B5/B12 -> 31.25 | C9: 現状アポ数 | D9: =sum(E9)+sum(G9:L9)+sum(N9:S9)+SUM(U9:Y9) -> 7 | E9: 1 | G9: 1 | H9: 0 | I9: 0 | J9: 1 | K9: 2 | L9: 1 | N9: 0 | O9: 1
A10: 目標コール数 | B10: =B9/B14 -> 1562.5 | C10: 現状コール数 | D10: =sum(E10)+sum(G10:L10)+sum(N10:S10)+SUM(U10:Y10) -> 537 | E10: 45 | G10: 43 | H10: 95 | I10: 57 | J10: 50 | K10: 30 | L10: 66 | N10: 73 | O10: 78
A11: 目標受注率 | B11: 0.2 | C11: 現状受注率 | D11: =D4/sum(D5:D6) -> 0.2
A12: 目標出席率 | B12: 0.8 | C12: 現状出席率 | D12: =sum(D5:D6)/D7 -> 1
A13: 目標商談転換率 | C13: 現状商談転換率 | D13: =SUM(D5:D6)/D9 -> 0.71428571
A14: 目標アポ転換率 | B14: 0.02 | C14: 現状アポ転換率 | D14: =D9/D10 -> 0.013035382
A16: 前川 | B16: 計画値 | D16: 現状 | E16: 土 | F16: 第1週 | G16: 月 | H16: 火 | I16: 水 | J16: 木 | K16: 金 | L16: 土 | M16: 第2週 | N16: 月 | O16: 火 | P16: 水 | Q16: 木 | R16: 金 | S16: 土 | T16: 第3週 | U16: 月 | V16: 火 | W16: 水 | X16: 木 | Y16: 金
E17: 45668 | F17: 45669 | G17: 45670 | H17: 45671 | I17: 45672 | J17: 45673 | K17: 45674 | L17: 45675 | M17: 45676 | N17: 45677 | O17: 45678 | P17: 45679 | Q17: 45680 | R17: 45681 | S17: 45682 | T17: 45683 | U17: 45684 | V17: 45685 | W17: 45686 | X17: 45687 | Y17: 45688
A18: 売上目標 | B18: 2640000 | C18: 現状売上 | D18: =sum(E18)+sum(G18:L18)+sum(N18:S18)+SUM(U18:Y18) -> 0
A19: 目標受注数 | B19: 12 | C19: 現状受注数 | D19: =sum(E19)+sum(G19:L19)+sum(N19:S19)+SUM(U19:Y19) -> 0
A20: 目標有効商談数 | B20: 40 | C20: 現状有効商談数 | D20: =sum(E20)+sum(G20:L20)+sum(N20:S20)+SUM(U20:Y20) -> 0
A21: 目標無効商談数 | C21: 現状無効商談数 | D21: =sum(E21)+sum(G21:L21)+sum(N21:S21)+SUM(U21:Y21) -> 0
C22: 当日アポ目標 | D22: =sum(E22)+sum(G22:L22)+sum(N22:S22)+SUM(U22:Y22) -> 0
C23: 商談予定 | D23: =sum(E23)+sum(G23:L23)+sum(N23:S23)+SUM(U23:Y23) -> 0
A24: 目標アポ数 | B24: 44 | C24: 現状アポ数 | D24: =sum(E24)+sum(G24:L24)+sum(N24:S24)+SUM(U24:Y24) -> 2 | E24: 0 | G24: 2 | I24: 0 | L24: 0
A25: 目標コール数 | B25: 2200 | C25: 現状コール数 | D25: =sum(E25)+sum(G25:L25)+sum(N25:S25)+SUM(U25:Y25) -> 150 | E25: 27 | G25: 26 | L25: 97
A26: 目標受注率 | B26: =B19/B20 -> 0.3 | C26: 現状受注率 | D26: =D19/sum(D20:D21) -> #DIV/0!
A27: 目標出席率 | B27: =B20/B24 -> 0.90909091 | C27: 現状出席率 | D27: =sum(D20:D21)/D23 -> #DIV/0!
A28: 目標商談転換率 | C28: 現状商談転換率 | D28: =SUM(D20:D21)/D24 -> 0
A29: 目標アポ転換率 | B29: =B24/B25 -> 0.02 | C29: 現状アポ転換率 | D29: =D24/D25 -> 0.013333333

Sheet 【2月】月間進捗管理シート
A1: 縞谷 | B1: 計画値 | D1: 現状 | E1: 土 | F1: 第1週 | G1: 月 | H1: 火 | I1: 水 | J1: 木 | K1: 金 | L1: 土 | M1: 第2週 | N1: 月 | O1: 火 | P1: 水 | Q1: 木 | R1: 金 | S1: 土 | T1: 第3週 | U1: 月 | V1: 火 | W1: 水 | X1: 木 | Y1: 金 | Z1: 土 | AA1: 日 | AB1: 月 | AC1: 火 | AD1: 水 | AE1: 木 | AF1: 金
E2: 45689 | F2: 45690 | G2: 45691 | H2: 45692 | I2: 45693 | J2: 45694 | K2: 45695 | L2: 45696 | M2: 45697 | N2: 45698 | O2: 45699 | P2: 45700 | Q2: 45701 | R2: 45702 | S2: 45703 | T2: 45704 | U2: 45705 | V2: 45706 | W2: 45707 | X2: 45708 | Y2: 45709 | Z2: 45710 | AA2: 45711 | AB2: 45712 | AC2: 45713 | AD2: 45714 | AE2: 45715 | AF2: 45716
A3: 売上目標 | B3: 1800000 | C3: 現状売上 | D3: =sum(E3)+sum(G3:L3)+sum(N3:S3)+SUM(U3:Y3) -> 0
A4: 目標受注数 | B4: 12 | C4: 現状受注数 | D4: =sum(E4)+sum(G4:L4)+sum(N4:S4)+SUM(U4:Y4) -> 0
A5: 目標有効商談数 | B5: =B4/B11 -> 40 | C5: 現状有効商談数 | D5: =sum(E5)+sum(G5:L5)+sum(N5:S5)+SUM(U5:Y5) -> 0
A6: 目標無効商談数 | C6: 現状無効商談数 | D6: =sum(E6)+sum(G6:L6)+sum(N6:S6)+SUM(U6:Y6) -> 0
C7: 商談予定 | D7: =sum(E7)+sum(G7:L7)+sum(N7:S7)+SUM(U7:Y7) -> 0
C8: 当日アポ目標 | D8: =sum(E8)+sum(G8:L8)+sum(N8:S8)+SUM(U8:Y8) -> 0
A9: 目標アポ数 | B9: =B5/B12 -> 47.058824 | C9: 現状アポ数 | D9: =sum(E9)+sum(G9:L9)+sum(N9:S9)+SUM(U9:Y9) -> 0
A10: 目標コール数 | B10: =B9/B14 -> 2352.9412 | C10: 現状コール数 | D10: =sum(E10)+sum(G10:L10)+sum(N10:S10)+SUM(U10:Y10) -> 0
A11: 目標受注率 | B11: 0.3 | C11: 現状受注率 | D11: =D4/sum(D5:D6) -> #DIV/0!
A12: 目標出席率 | B12: 0.85 | C12: 現状出席率 | D12: =sum(D5:D6)/D7 -> #DIV/0!
C13: 現状商談転換率 | D13: =SUM(D5:D6)/D9 -> #DIV/0!
A14: 目標アポ転換率 | B14: 0.02 | C14: 現状アポ転換率 | D14: =D9/D10 -> #DIV/0!
A16: 前川 | B16: 計画値 | D16: 現状 | E16: 土 | F16: 第1週 | G16: 月 | H16: 火 | I16: 水 | J16: 木 | K16: 金 | L16: 土 | M16: 第2週 | N16: 月 | O16: 火 | P16: 水 | Q16: 木 | R16: 金 | S16: 土 | T16: 第3週 | U16: 月 | V16: 火 | W16: 水 | X16: 木 | Y16: 金 | Z16: 土 | AA16: 日 | AB16: 月 | AC16: 火 | AD16: 水 | AE16: 木 | AF16: 金
E17: 45689 | F17: 45690 | G17: 45691 | H17: 45692 | I17: 45693 | J17: 45694 | K17: 45695 | L17: 45696 | M17: 45697 | N17: 45698 | O17: 45699 | P17: 45700 | Q17: 45701 | R17: 45702 | S17: 45703 | T17: 45704 | U17: 45705 | V17: 45706 | W17: 45707 | X17: 45708 | Y17: 45709 | Z17: 45710 | AA17: 45711 | AB17: 45712 | AC17: 45713 | AD17: 45714 | AE17: 45715 | AF17: 45716
A18: 売上目標 | C18: 現状売上 | D18: =sum(E18)+sum(G18:L18)+sum(N18:S18)+SUM(U18:Y18) -> 0
A19: 目標受注数 | C19: 現状受注数 | D19: =sum(E19)+sum(G19:L19)+sum(N19:S19)+SUM(U19:Y19) -> 0
A20: 目標有効商談数 | C20: 現状有効商談数 | D20: =sum(E20)+sum(G20:L20)+sum(N20:S20)+SUM(U20:Y20) -> 0
A21: 目標無効商談数 | C21: 現状無効商談数 | D21: =sum(E21)+sum(G21:L21)+sum(N21:S21)+SUM(U21:Y21) -> 0
C22: 当日アポ目標 | D22: =sum(E22)+sum(G22:L22)+sum(N22:S22)+SUM(U22:Y22) -> 0
C23: 商談予定 | D23: =sum(E23)+sum(G23:L23)+sum(N23:S23)+SUM(U23:Y23) -> 0
A24: 目標アポ数 | C24: 現状アポ数 | D24: =sum(E24)+sum(G24:L24)+sum(N24:S24)+SUM(U24:Y24) -> 0
A25: 目標コール数 | C25: 現状コール数 | D25: =sum(E25)+sum(G25:L25)+sum(N25:S25)+SUM(U25:Y25) -> 0
A26: 目標受注率 | C26: 現状受注率 | D26: =D19/sum(D20:D21) -> #DIV/0!
A27: 目標出席率 | C27: 現状出席率 | D27: =sum(D20:D21)/D23 -> #DIV/0!
C28: 現状商談転換率 | D28: =SUM(D20:D21)/D24 -> #DIV/0!
A29: 目標アポ転換率 | C29: 現状アポ転換率 | D29: =D24/D25 -> #DIV/0!

Sheet 【4月】月間進捗管理シート
A1: 全体 | B1: 計画値 | D1: 現状 | E1: 火 | F1: 水 | G1: 木 | H1: 金 | I1: 土 | J1: 日 | K1: 月 | L1: 火 | M1: 水 | N1: 木 | O1: 金 | P1: 土 | Q1: 日 | R1: 月 | S1: 火 | T1: 水 | U1: 木 | V1: 金 | W1: 土 | X1: 日 | Y1: 月 | Z1: 火 | AA1: 水 | AB1: 木 | AC1: 金 | AD1: 土 | AE1: 日 | AF1: 月 | AG1: 火 | AH1: 水
E2: 45748 | F2: 45749 | G2: 45750 | H2: 45751 | I2: 45752 | J2: 45753 | K2: 45754 | L2: 45755 | M2: 45756 | N2: 45757 | O2: 45758 | P2: 45759 | Q2: 45760 | R2: 45761 | S2: 45762 | T2: 45763 | U2: 45764 | V2: 45765 | W2: 45766 | X2: 45767 | Y2: 45768 | Z2: 45769 | AA2: 45770 | AB2: 45771 | AC2: 45772 | AD2: 45773 | AE2: 45774 | AF2: 45775 | AG2: 45776 | AH2: 45777
A3: 売上目標 | B3: 2800000 | C3: 現状売上 | D3: =I3+Q3+X3+AE3+AI3 -> #VALUE! | E3: =E18+E33 -> 0 | F3: =F18+F33 -> 0 | G3: =G18+G33 -> 0 | H3: =H18+H33 -> 0 | I3: =sum(E3:H3) -> 0 | K3: =K18+K33 -> 0 | L3: =L18+L33 -> 0 | M3: =M18+M33 -> #VALUE! | N3: =N18+N33 -> #VALUE! | O3: =O18+O33 -> 0 | P3: =P18+P33 -> 0 | Q3: =sum(K3:P3) -> #VALUE! | R3: =R18+R33 -> 235000 | S3: =S18+S33 -> #VALUE! | T3: =T18+T33 -> #VALUE! | U3: =U18+U33 -> #VALUE! | V3: =V18+V33 -> 180000 | W3: =W18+W33 -> 0 | X3: =sum(R3:W3) -> #VALUE! | Y3: =Y18+Y33 -> 0 | Z3: =Z18+Z33 -> 0 | AA3: =AA18+AA33 -> 470000 | AB3: =AB18+AB33 -> 0 | AC3: =AC18+AC33 -> 0 | AD3: =AD18+AD33 -> 0 | AE3: =sum(Y3:AD3) -> 470000 | AF3: =AF18+AF33 -> #VALUE! | AG3: =AG18+AG33 -> #VALUE! | AH3: =AH18+AH33 -> #VALUE! | AI3: =sum(AF3:AH3) -> #VALUE!
A4: 目標受注数 | B4: 14 | C4: 現状受注数 | D4: =I4+Q4+X4+AE4+AI4 -> 6 | E4: =E19+E34 -> 0 | F4: =F19+F34 -> 0 | G4: =G19+G34 -> 0 | H4: =H19+H34 -> 0 | I4: =sum(E4:H4) -> 0 | K4: =K19+K34 -> 0 | L4: =L19+L34 -> 0 | M4: =M19+M34 -> 0 | N4: =N19+N34 -> 0 | O4: =O19+O34 -> 0 | P4: =P19+P34 -> 0 | Q4: =SUM(K4:P4) -> 0 | R4: =R19+R34 -> 1 | S4: =S19+S34 -> 0 | T4: =T19+T34 -> 2 | U4: =U19+U34 -> 0 | V4: =V19+V34 -> 1 | W4: =W19+W34 -> 0 | X4: =sum(R4:W4) -> 4 | Y4: =Y19+Y34 -> 0 | Z4: =Z19+Z34 -> 0 | AA4: =AA19+AA34 -> 2 | AB4: =AB19+AB34 -> 0 | AC4: =AC19+AC34 -> 0 | AD4: =AD19+AD34 -> 0 | AE4: =sum(Y4:AD4) -> 2 | AF4: =AF19+AF34 -> 0 | AG4: =AG19+AG34 -> 0 | AH4: =AH19+AH34 -> 0 | AI4: =sum(AF4:AH4) -> 0
A5: 目標有効商談数 | B5: =B4/B8 -> 56 | C5: 現状有効商談数 | D5: =I5+Q5+X5+AE5+AI5 -> 25 | E5: =E20+E35 -> 0 | F5: =F20+F35 -> 0 | G5: =G20+G35 -> 0 | H5: =H20+H35 -> 2 | I5: =sum(E5:H5) -> 2 | K5: =K20+K35 -> 2 | L5: =L20+L35 -> 0 | M5: =M20+M35 -> 0 | N5: =N20+N35 -> 1 | O5: =O20+O35 -> 3 | P5: =P20+P35 -> 2 | Q5: =SUM(K5:P5) -> 8 | R5: =R20+R35 -> 3 | S5: =S20+S35 -> 3 | T5: =T20+T35 -> 1 | U5: =U20+U35 -> 3 | V5: =V20+V35 -> 1 | W5: =W20+W35 -> 1 | X5: =sum(R5:W5) -> 12 | Y5: =Y20+Y35 -> 0 | Z5: =Z20+Z35 -> 0 | AA5: =AA20+AA35 -> 1 | AB5: =AB20+AB35 -> 0 | AC5: =AC20+AC35 -> 0 | AD5: =AD20+AD35 -> 0 | AE5: =sum(Y5:AD5) -> 1 | AF5: =AF20+AF35 -> 1 | AG5: =AG20+AG35 -> 1 | AH5: =AH20+AH35 -> 0 | AI5: =sum(AF5:AH5) -> 2
A6: 目標アポ数 | B6: =B5/B9 -> 80 | C6: 現状無効商談数 | D6: =I6+Q6+X6+AE6+AI6 -> 0 | E6: =E21+E36 -> 0 | F6: =F21+F36 -> 0 | G6: =G21+G36 -> 0 | H6: =H21+H36 -> 0 | I6: =sum(E6:H6) -> 0 | K6: =K21+K36 -> 0 | L6: =L21+L36 -> 0 | M6: =M21+M36 -> 0 | N6: =N21+N36 -> 0 | O6: =O21+O36 -> 0 | P6: =P21+P36 -> 0 | Q6: =SUM(K6:P6) -> 0 | R6: =R21+R36 -> 0 | S6: =S21+S36 -> 0 | T6: =T21+T36 -> 0 | U6: =U21+U36 -> 0 | V6: =V21+V36 -> 0 | W6: =W21+W36 -> 0 | X6: =sum(R6:W6) -> 0 | Y6: =Y21+Y36 -> 0 | Z6: =Z21+Z36 -> 0 | AA6: =AA21+AA36 -> 0 | AB6: =AB21+AB36 -> 0 | AC6: =AC21+AC36 -> 0 | AD6: =AD21+AD36 -> 0 | AE6: =sum(Y6:AD6) -> 0 | AF6: =AF21+AF36 -> 0 | AG6: =AG21+AG36 -> 0 | AH6: =AH21+AH36 -> 0 | AI6: =sum(AF6:AH6) -> 0
A7: 目標コール数 | B7: =B6/B10 -> 4000 | C7: 新規商談予定 | D7: =I7+Q7+X7+AE7+AI7 -> 39 | E7: =E22+E37 -> 0 | F7: =F22+F37 -> 0 | G7: =G22+G37 -> 2 | H7: =H22+H37 -> 2 | I7: =sum(E7:H7) -> 4 | K7: =K22+K37 -> 3 | L7: =L22+L37 -> 1 | M7: =M22+M37 -> 2 | N7: =N22+N37 -> 2 | O7: =O22+O37 -> 3 | P7: =P22+P37 -> 3 | Q7: =SUM(K7:P7) -> 14 | R7: =R22+R37 -> 3 | S7: =S22+S37 -> 3 | T7: =T22+T37 -> 2 | U7: =U22+U37 -> 5 | V7: =V22+V37 -> 2 | W7: =W22+W37 -> 1 | X7: =sum(R7:W7) -> 16 | Y7: =Y22+Y37 -> 0 | Z7: =Z22+Z37 -> 0 | AA7: =AA22+AA37 -> 1 | AB7: =AB22+AB37 -> 1 | AC7: =AC22+AC37 -> 0 | AD7: =AD22+AD37 -> 1 | AE7: =sum(Y7:AD7) -> 3 | AF7: =AF22+AF37 -> 1 | AG7: =AG22+AG37 -> 1 | AH7: =AH22+AH37 -> 0 | AI7: =sum(AF7:AH7) -> 2
A8: 目標受注率 | B8: 0.25 | C8: 当日アポ目標 | D8: =I8+Q8+X8+AE8+AI8 -> 93 | E8: =E23+E38 -> 0 | F8: =F23+F38 -> 4 | G8: =G23+G38 -> 5 | H8: =H23+H38 -> 6 | I8: =sum(E8:H8) -> 15 | K8: =K23+K38 -> 3 | L8: =L23+L38 -> 6 | M8: =M23+M38 -> 6 | N8: =N23+N38 -> 6 | O8: =O23+O38 -> 5 | P8: =P23+P38 -> 6 | Q8: =SUM(K8:P8) -> 32 | R8: =R23+R38 -> 5 | S8: =S23+S38 -> 4 | T8: =T23+T38 -> 5 | U8: =U23+U38 -> 5 | V8: =V23+V38 -> 6 | W8: =W23+W38 -> 2 | X8: =sum(R8:W8) -> 27 | Y8: =Y23+Y38 -> 0 | Z8: =Z23+Z38 -> 0 | AA8: =AA23+AA38 -> 2 | AB8: =AB23+AB38 -> 4 | AC8: =AC23+AC38 -> 4 | AD8: =AD23+AD38 -> 2 | AE8: =sum(Y8:AD8) -> 12 | AF8: =AF23+AF38 -> 2 | AG8: =AG23+AG38 -> 3 | AH8: =AH23+AH38 -> 2 | AI8: =sum(AF8:AH8) -> 7
A9: 目標出席率 | B9: 0.7 | C9: 現状アポ数 | D9: =I9+Q9+X9+AE9+AI9 -> 41 | E9: =E24+E39 -> 0 | F9: =F24+F39 -> 2 | G9: =G24+G39 -> 5 | H9: =H24+H39 -> 3 | I9: =sum(E9:H9) -> 10 | K9: =K24+K39 -> 1 | L9: =L24+L39 -> 2 | M9: =M24+M39 -> 3 | N9: =N24+N39 -> 2 | O9: =O24+O39 -> 3 | P9: =P24+P39 -> 2 | Q9: =SUM(K9:P9) -> 13 | R9: =R24+R39 -> 3 | S9: =S24+S39 -> 1 | T9: =T24+T39 -> 2 | U9: =U24+U39 -> 1 | V9: =V24+V39 -> 2 | W9: =W24+W39 -> 0 | X9: =sum(R9:W9) -> 9 | Y9: =Y24+Y39 -> 0 | Z9: =Z24+Z39 -> 0 | AA9: =AA24+AA39 -> 1 | AB9: =AB24+AB39 -> 0 | AC9: =AC24+AC39 -> 1 | AD9: =AD24+AD39 -> 0 | AE9: =sum(Y9:AD9) -> 2 | AF9: =AF24+AF39 -> 2 | AG9: =AG24+AG39 -> 4 | AH9: =AH24+AH39 -> 1 | AI9: =sum(AF9:AH9) -> 7
A10: 目標アポ転換率 | B10: 0.02 | C10: 現状コール数 | D10: =I10+Q10+X10+AE10+AI10 -> 4219 | E10: =E25+E40 -> 0 | F10: =F25+F40 -> 220 | G10: =G25+G40 -> 237 | H10: =H25+H40 -> 191 | I10: =sum(E10:H10) -> 648 | K10: =K25+K40 -> 30 | L10: =L25+L40 -> 223 | M10: =M25+M40 -> 225 | N10: =N25+N40 -> 183 | O10: =O25+O40 -> 180 | P10: =P25+P40 -> 258 | Q10: =SUM(K10:P10) -> 1099 | R10: =R25+R40 -> 164 | S10: =S25+S40 -> 174 | T10: =T25+T40 -> 177 | U10: =U25+U40 -> 213 | V10: =V25+V40 -> 213 | W10: =W25+W40 -> 0 | X10: =sum(R10:W10) -> 941 | Y10: =Y25+Y40 -> 0 | Z10: =Z25+Z40 -> 0 | AA10: =AA25+AA40 -> 149 | AB10: =AB25+AB40 -> 315 | AC10: =AC25+AC40 -> 230 | AD10: =AD25+AD40 -> 114 | AE10: =sum(Y10:AD10) -> 808 | AF10: =AF25+AF40 -> 268 | AG10: =AG25+AG40 -> 298 | AH10: =AH25+AH40 -> 157 | AI10: =sum(AF10:AH10) -> 723
A11: 1日の平均受注数 | B11: =D4/23 -> 0.26086957 | C11: 現状受注率 | D11: =D4/sum(D5:D6) -> 0.24 | E11: 1週間の平均受注数 | I11: =I4/4 -> 0 | K11: 1週間の平均受注数 | Q11: =Q4/6 -> 0 | R11: 1週間の平均受注数 | X11: =X4/6 -> 0.66666667 | Y11: 1週間の平均受注数 | AE11: =AE4/6 -> 0.33333333 | AF11: 1週間の平均受注数 | AI11: =AI4/3 -> 0
A12: 1日の平均消化数 | B12: =D5/23 -> 1.0869565 | C12: 現状出席率 | D12: =sum(D5:D6)/D7 -> 0.64102564 | E12: 1週間の平均消化数 | I12: =I5/3 -> 0.66666667 | K12: 1週間の平均消化数 | Q12: =Q5/6 -> 1.3333333 | R12: 1週間の平均消化数 | X12: =X5/6 -> 2 | Y12: 1週間の平均消化数 | AE12: =AE5/6 -> 0.16666667 | AF12: 1週間の平均消化数 | AI12: =AI5/3 -> 0.66666667
A13: 1日の平均アポ数 | B13: =D9/23 -> 1.7826087 | C13: 現状商談転換率 | D13: =SUM(D5:D6)/D9 -> 0.6097561 | E13: 1週間の平均アポ数 | I13: =I9/3 -> 3.3333333 | K13: 1週間の平均アポ数 | Q13: =Q9/6 -> 2.1666667 | R13: 1週間の平均アポ数 | X13: =X9/6 -> 1.5 | Y13: 1週間の平均アポ数 | AE13: =AE9/6 -> 0.33333333 | AF13: 1週間の平均アポ数 | AI13: =AI9/3 -> 2.3333333
A14: 1日の平均コール数 | B14: =D10/23 -> 183.43478 | C14: 現状アポ転換率 | D14: =D9/D10 -> 0.0097179426 | E14: 1週間の平均コール数 | I14: =I10/3 -> 216 | K14: 1週間の平均コール数 | Q14: =Q10/6 -> 183.16667 | R14: 1週間の平均コール数 | X14: =X10/6 -> 156.83333 | Y14: 1週間の平均コール数 | AE14: =AE10/6 -> 134.66667 | AF14: 1週間の平均コール数 | AI14: =AI10/3 -> 241
A16: 縞谷 | B16: 計画値 | D16: 現状 | E16: 火 | F16: 水 | G16: 木 | H16: 金 | I16: 土 | J16: 日 | K16: 月 | L16: 火 | M16: 水 | N16: 木 | O16: 金 | P16: 土 | Q16: 日 | R16: 月 | S16: 火 | T16: 水 | U16: 木 | V16: 金 | W16: 土 | X16: 日 | Y16: 月 | Z16: 火 | AA16: 水 | AB16: 木 | AC16: 金 | AD16: 土 | AE16: 日 | AF16: 月 | AG16: 火 | AH16: 水
E17: 45748 | F17: 45749 | G17: 45750 | H17: 45751 | I17: 45752 | J17: 45753 | K17: 45754 | L17: 45755 | M17: 45756 | N17: 45757 | O17: 45758 | P17: 45759 | Q17: 45760 | R17: 45761 | S17: 45762 | T17: 45763 | U17: 45764 | V17: 45765 | W17: 45766 | X17: 45767 | Y17: 45768 | Z17: 45769 | AA17: 45770 | AB17: 45771 | AC17: 45772 | AD17: 45773 | AE17: 45774 | AF17: 45775 | AG17: 45776 | AH17: 45777
A18: 売上目標 | B18: 1600000 | C18: 現状売上 | D18: =I18+Q18+X18+AE18+AI18 -> 1355000 | I18: =sum(E18:H18) -> 0 | Q18: =sum(K18:P18) -> 0 | R18: 235000 | T18: 470000 | V18: 180000 | X18: =sum(R18:W18) -> 885000 | AA18: 470000 | AE18: =sum(Y18:AD18) -> 470000 | AI18: =sum(AF18:AH18) -> 0
A19: 目標受注数 | B19: 9 | C19: 現状受注数 | D19: =I19+Q19+X19+AE19+AI19 -> 6 | I19: =sum(E19:H19) -> 0 | Q19: =SUM(K19:P19) -> 0 | R19: 1 | T19: 2 | V19: 1 | X19: =sum(R19:W19) -> 4 | AA19: 2 | AE19: =sum(Y19:AD19) -> 2 | AI19: =sum(AF19:AH19) -> 0
A20: 目標有効商談数 | B20: =B19/B23 -> 36 | C20: 現状有効商談数 | D20: =I20+Q20+X20+AE20+AI20 -> 20 | G20: 0 | H20: 2 | I20: =sum(E20:H20) -> 2 | K20: 2 | L20: 0 | N20: 1 | O20: 3 | P20: 2 | Q20: =SUM(K20:P20) -> 8 | R20: 3 | S20: 3 | T20: 1 | U20: 2 | V20: 1 | X20: =sum(R20:W20) -> 10 | AE20: =sum(Y20:AD20) -> 0 | AI20: =sum(AF20:AH20) -> 0
A21: 目標アポ数 | B21: =B20/B24 -> 51.428571 | C21: 現状無効商談数 | D21: =I21+Q21+X21+AE21+AI21 -> 0 | I21: =sum(E21:H21) -> 0 | Q21: =SUM(K21:P21) -> 0 | X21: =sum(R21:W21) -> 0 | AE21: =sum(Y21:AD21) -> 0 | AI21: =sum(AF21:AH21) -> 0
A22: 目標コール数 | B22: =B21/B25 -> 2571.4286 | C22: 新規商談予定 | D22: =I22+Q22+X22+AE22+AI22 -> 32 | G22: 1 | H22: 2 | I22: =sum(E22:H22) -> 3 | K22: 3 | L22: 1 | M22: 2 | N22: 2 | O22: 3 | P22: 3 | Q22: =SUM(K22:P22) -> 14 | R22: 3 | S22: 3 | T22: 2 | U22: 3 | V22: 2 | X22: =sum(R22:W22) -> 13 | AB22: 1 | AD22: 1 | AE22: =sum(Y22:AD22) -> 2 | AI22: =sum(AF22:AH22) -> 0
A23: 目標受注率 | B23: 0.25 | C23: 当日アポ目標 | D23: =I23+Q23+X23+AE23+AI23 -> 38 | F23: 2 | G23: 2 | H23: 3 | I23: =sum(E23:H23) -> 7 | K23: 3 | L23: 3 | M23: 3 | N23: 2 | O23: 2 | P23: 3 | Q23: =SUM(K23:P23) -> 16 | R23: 2 | S23: 1 | T23: 2 | U23: 3 | V23: 3 | X23: =sum(R23:W23) -> 11 | AB23: 2 | AC23: 2 | AE23: =sum(Y23:AD23) -> 4 | AI23: =sum(AF23:AH23) -> 0
A24: 目標出席率 | B24: 0.7 | C24: 現状アポ数 | D24: =I24+Q24+X24+AE24+AI24 -> 24 | F24: 2 | G24: 4 | H24: 3 | I24: =sum(E24:H24) -> 9 | K24: 1 | L24: 2 | M24: 1 | N24: 0 | O24: 1 | P24: 1 | Q24: =SUM(K24:P24) -> 6 | R24: 2 | S24: 1 | T24: 1 | U24: 1 | V24: 0 | X24: =sum(R24:W24) -> 5 | AC24: 1 | AE24: =sum(Y24:AD24) -> 1 | AF24: 1 | AG24: 2 | AI24: =sum(AF24:AH24) -> 3
A25: 目標アポ転換率 | B25: 0.02 | C25: 現状コール数 | D25: =I25+Q25+X25+AE25+AI25 -> 1564 | F25: 88 | G25: 70 | H25: 70 | I25: =sum(E25:H25) -> 228 | K25: 30 | L25: 80 | M25: 95 | N25: 80 | O25: 40 | P25: 106 | Q25: =SUM(K25:P25) -> 431 | R25: 43 | S25: 33 | T25: 60 | U25: 105 | V25: 47 | X25: =sum(R25:W25) -> 288 | AB25: 146 | AC25: 230 | AE25: =sum(Y25:AD25) -> 376 | AF25: 119 | AG25: 122 | AI25: =sum(AF25:AH25) -> 241
A26: 1日の平均受注数 | B26: =D19/23 -> 0.26086957 | C26: 現状受注率 | D26: =D19/sum(D20:D21) -> 0.3 | E26: 1週間の平均受注数 | I26: =I19/4 -> 0 | K26: 1週間の平均受注数 | Q26: =Q19/6 -> 0 | R26: 1週間の平均受注数 | X26: =X19/6 -> 0.66666667 | Y26: 1週間の平均受注数 | AE26: =AE19/6 -> 0.33333333 | AF26: 1週間の平均受注数 | AI26: =AI19/3 -> 0
A27: 1日の平均消化数 | B27: =D20/23 -> 0.86956522 | C27: 現状出席率 | D27: =sum(D20:D21)/D22 -> 0.625 | E27: 1週間の平均消化数 | I27: =I20/3 -> 0.66666667 | K27: 1週間の平均消化数 | Q27: =Q20/6 -> 1.3333333 | R27: 1週間の平均消化数 | X27: =X20/6 -> 1.6666667 | Y27: 1週間の平均消化数 | AE27: =AE20/6 -> 0 | AF27: 1週間の平均消化数 | AI27: =AI20/3 -> 0
A28: 1日の平均アポ数 | B28: =D24/23 -> 1.0434783 | C28: 現状商談転換率 | D28: =SUM(D20:D21)/D24 -> 0.83333333 | E28: 1週間の平均アポ数 | I28: =I24/3 -> 3 | K28: 1週間の平均アポ数 | Q28: =Q24/6 -> 1 | R28: 1週間の平均アポ数 | X28: =X24/6 -> 0.83333333 | Y28: 1週間の平均アポ数 | AE28: =AE24/6 -> 0.16666667 | AF28: 1週間の平均アポ数 | AI28: =AI24/3 -> 1
A29: 1日の平均コール数 | B29: =D25/23 -> 68 | C29: 現状アポ転換率 | D29: =D24/D25 -> 0.015345269 | E29: 1週間の平均コール数 | I29: =I25/3 -> 76 | K29: 1週間の平均コール数 | Q29: =Q25/6 -> 71.833333 | R29: 1週間の平均コール数 | X29: =X25/6 -> 48 | Y29: 1週間の平均コール数 | AE29: =AE25/6 -> 62.666667 | AF29: 1週間の平均コール数 | AI29: =AI25/3 -> 80.333333
A31: 前川 | B31: 計画値 | D31: 現状 | E31: 火 | F31: 水 | G31: 木 | H31: 金 | I31: 土 | J31: 日 | K31: 月 | L31: 火 | M31: 水 | N31: 木 | O31: 金 | P31: 土 | Q31: 日 | R31: 月 | S31: 火 | T31: 水 | U31: 木 | V31: 金 | W31: 土 | X31: 日 | Y31: 月 | Z31: 火 | AA31: 水 | AB31: 木 | AC31: 金 | AD31: 土 | AE31: 日 | AF31: 月 | AG31: 火 | AH31: 水
E32: 45748 | F32: 45749 | G32: 45750 | H32: 45751 | I32: 45752 | J32: 45753 | K32: 45754 | L32: 45755 | M32: 45756 | N32: 45757 | O32: 45758 | P32: 45759 | Q32: 45760 | R32: 45761 | S32: 45762 | T32: 45763 | U32: 45764 | V32: 45765 | W32: 45766 | X32: 45767 | Y32: 45768 | Z32: 45769 | AA32: 45770 | AB32: 45771 | AC32: 45772 | AD32: 45773 | AE32: 45774 | AF32: 45775 | AG32: 45776 | AH32: 45777
A33: 売上目標 | B33: 1200000 | C33: 現状売上 | D33: =sum(E33:AH33) -> 0 | I33: =sum(E33:H33) -> 0 | Q33: =sum(K33:P33) -> 0 | X33: =sum(R33:W33) -> 0 | AE33: =sum(Y33:AD33) -> 0 | AI33: =sum(AF33:AH33) -> 0
A34: 目標受注数 | B34: 8 | C34: 現状受注数 | D34: =sum(E34:AH34) -> 0 | I34: =sum(E34:H34) -> 0 | Q34: =SUM(K34:P34) -> 0 | X34: =sum(R34:W34) -> 0 | AE34: =sum(Y34:AD34) -> 0 | AI34: =sum(AF34:AH34) -> 0
A35: 目標有効商談数 | B35: =B34/B38 -> 40 | C35: 現状有効商談数 | D35: =sum(E35:AH35) -> 8 | I35: =sum(E35:H35) -> 0 | Q35: =SUM(K35:P35) -> 0 | U35: 1 | W35: 1 | X35: =sum(R35:W35) -> 2 | AA35: 1 | AE35: =sum(Y35:AD35) -> 1 | AF35: 1 | AG35: 1 | AI35: =sum(AF35:AH35) -> 2
A36: 目標アポ数 | B36: =B35/B39 -> 50 | C36: 現状無効商談数 | D36: =sum(E36:AH36) -> 0 | I36: =sum(E36:H36) -> 0 | Q36: =SUM(K36:P36) -> 0 | X36: =sum(R36:W36) -> 0 | AE36: =sum(Y36:AD36) -> 0 | AI36: =sum(AF36:AH36) -> 0
A37: 目標コール数 | B37: =B36/B40 -> 2500 | C37: 新規商談予定 | D37: =sum(E37:AH37) -> 12 | G37: 1 | H37: 0 | I37: =sum(E37:H37) -> 1 | Q37: =SUM(K37:P37) -> 0 | U37: 2 | W37: 1 | X37: =sum(R37:W37) -> 3 | AA37: 1 | AE37: =sum(Y37:AD37) -> 1 | AF37: 1 | AG37: 1 | AI37: =sum(AF37:AH37) -> 2
A38: 目標受注率 | B38: 0.2 | C38: 当日アポ目標 | D38: =sum(E38:AH38) -> 103 | F38: 2 | G38: 3 | H38: 3 | I38: =sum(E38:H38) -> 8 | L38: 3 | M38: 3 | N38: 4 | O38: 3 | P38: 3 | Q38: =SUM(K38:P38) -> 16 | R38: 3 | S38: 3 | T38: 3 | U38: 2 | V38: 3 | W38: 2 | X38: =sum(R38:W38) -> 16 | AA38: 2 | AB38: 2 | AC38: 2 | AD38: 2 | AE38: =sum(Y38:AD38) -> 8 | AF38: 2 | AG38: 3 | AH38: 2 | AI38: =sum(AF38:AH38) -> 7
A39: 目標出席率 | B39: 0.8 | C39: 現状アポ数 | D39: =sum(E39:AH39) -> 30 | F39: 0 | G39: 1 | H39: 0 | I39: =sum(E39:H39) -> 1 | L39: 0 | M39: 2 | N39: 2 | O39: 2 | P39: 1 | Q39: =SUM(K39:P39) -> 7 | R39: 1 | S39: 0 | T39: 1 | V39: 2 | W39: 0 | X39: =sum(R39:W39) -> 4 | AA39: 1 | AB39: 0 | AE39: =sum(Y39:AD39) -> 1 | AF39: 1 | AG39: 2 | AH39: 1 | AI39: =sum(AF39:AH39) -> 4
A40: 目標アポ転換率 | B40: 0.02 | C40: 現状コール数 | D40: =I40+Q40+X40+AE40+AI40 -> 2655 | F40: 132 | G40: 167 | H40: 121 | I40: =sum(E40:H40) -> 420 | L40: 143 | M40: 130 | N40: 103 | O40: 140 | P40: 152 | Q40: =SUM(K40:P40) -> 668 | R40: 121 | S40: 141 | T40: 117 | U40: 108 | V40: 166 | X40: =sum(R40:W40) -> 653 | AA40: 149 | AB40: 169 | AD40: 114 | AE40: =sum(Y40:AD40) -> 432 | AF40: 149 | AG40: 176 | AH40: 157 | AI40: =sum(AF40:AH40) -> 482
A41: 1日の平均受注数 | B41: =D34/23 -> 0 | C41: 現状受注率 | D41: =D34/sum(D35:D36) -> 0 | E41: 1週間の平均受注数 | I41: =I34/4 -> 0 | K41: 1週間の平均受注数 | Q41: =Q34/6 -> 0 | R41: 1週間の平均受注数 | X41: =X34/6 -> 0 | Y41: 1週間の平均受注数 | AE41: =AE34/6 -> 0 | AF41: 1週間の平均受注数 | AI41: =AI34/3 -> 0
A42: 1日の平均消化数 | B42: =D35/23 -> 0.34782609 | C42: 現状出席率 | D42: =sum(D35:D36)/D37 -> 0.66666667 | E42: 1週間の平均消化数 | I42: =I35/3 -> 0 | K42: 1週間の平均消化数 | Q42: =Q35/6 -> 0 | R42: 1週間の平均消化数 | X42: =X35/6 -> 0.33333333 | Y42: 1週間の平均消化数 | AE42: =AE35/6 -> 0.16666667 | AF42: 1週間の平均消化数 | AI42: =AI35/3 -> 0.66666667
...

Sheet 【4月】週次振り返り用
A1: 全体 | B1: 第１週 | G1: 第2週 | L1: 第3週 | Q1: 第4週 | V1: 第5週
B2: 45749 | C2: ~ | E2: 45751 | G2: 45754 | H2: ~ | J2: 45759 | L2: 45761 | M2: ~ | O2: 45766 | Q2: 45768 | R2: ~ | T2: 45773 | V2: 45775 | W2: ~ | Y2: 45777
B3: 売上 | C3: ='【4月】月間進捗管理シート'!I3 -> 0 | D3: 平均単価 | E3: =C3/C4 -> #DIV/0! | G3: 売上 | H3: ='【4月】月間進捗管理シート'!Q3 -> #VALUE! | I3: 平均単価 | J3: =H3/H4 -> #VALUE! | L3: 売上 | M3: ='【4月】月間進捗管理シート'!X3 -> #VALUE! | N3: 平均単価 | O3: =M3/M4 -> #VALUE! | Q3: 売上 | S3: 平均単価 | T3: =R3/R4 -> #DIV/0! | V3: 売上 | X3: 平均単価 | Y3: =W3/W4 -> #DIV/0!
B4: 受注数 | C4: ='【4月】月間進捗管理シート'!I4 -> 0 | D4: 現状受注率 | E4: =C5/C4 -> #DIV/0! | G4: 受注数 | H4: ='【4月】月間進捗管理シート'!Q4 -> 0 | I4: 現状受注率 | J4: =H5/H4 -> #DIV/0! | L4: 受注数 | M4: ='【4月】月間進捗管理シート'!X4 -> 4 | N4: 現状受注率 | O4: =M5/M4 -> 3 | Q4: 受注数 | S4: 現状受注率 | T4: =R5/R4 -> #DIV/0! | V4: 受注数 | X4: 現状受注率 | Y4: =W5/W4 -> #DIV/0!
B5: 有効商談数 | C5: ='【4月】月間進捗管理シート'!I5 -> 2 | D5: 現状出席率 | E5: =C5/C7 -> 0.5 | G5: 有効商談数 | H5: ='【4月】月間進捗管理シート'!Q5 -> 8 | I5: 現状出席率 | J5: =H5/H7 -> 0.57142857 | L5: 有効商談数 | M5: ='【4月】月間進捗管理シート'!X5 -> 12 | N5: 現状出席率 | O5: =M5/M7 -> 0.75 | Q5: 有効商談数 | S5: 現状出席率 | T5: =R5/R7 -> #DIV/0! | V5: 有効商談数 | X5: 現状出席率 | Y5: =W5/W7 -> #DIV/0!
B6: 無効商談数 | C6: ='【4月】月間進捗管理シート'!I6 -> 0 | D6: 現状アポ転換率 | E6: =C8/C9 -> 0.015432099 | G6: 無効商談数 | H6: ='【4月】月間進捗管理シート'!Q6 -> 0 | I6: 現状アポ転換率 | J6: =H8/H9 -> 0.011828935 | L6: 無効商談数 | M6: ='【4月】月間進捗管理シート'!X6 -> 0 | N6: 現状アポ転換率 | O6: =M8/M9 -> 0.0095642933 | Q6: 無効商談数 | S6: 現状アポ転換率 | T6: =R8/R9 -> #DIV/0! | V6: 無効商談数 | X6: 現状アポ転換率 | Y6: =W8/W9 -> #DIV/0!
B7: 新規商談予定 | C7: ='【4月】月間進捗管理シート'!I7 -> 4 | D7: アポ→商談 | E7: 4 | G7: 新規商談予定 | H7: ='【4月】月間進捗管理シート'!Q7 -> 14 | I7: アポ→商談 | J7: 3 | L7: 新規商談予定 | M7: ='【4月】月間進捗管理シート'!X7 -> 16 | N7: アポ→商談 | O7: 3 | Q7: 新規商談予定 | S7: アポ→商談 | V7: 新規商談予定 | X7: アポ→商談
B8: 現状アポ数 | C8: ='【4月】月間進捗管理シート'!I9 -> 10 | D8: アポ→受注 | E8: 10 | G8: 現状アポ数 | H8: ='【4月】月間進捗管理シート'!Q9 -> 13 | I8: アポ→受注 | J8: 10 | L8: 現状アポ数 | M8: ='【4月】月間進捗管理シート'!X9 -> 9 | N8: アポ→受注 | O8: 10 | Q8: 現状アポ数 | S8: アポ→受注 | V8: 現状アポ数 | X8: アポ→受注
B9: 現状コール数 | C9: ='【4月】月間進捗管理シート'!I10 -> 648 | D9: アポ→通過 | E9: 17 | G9: 現状コール数 | H9: ='【4月】月間進捗管理シート'!Q10 -> 1099 | I9: アポ→通過 | J9: 16 | L9: 現状コール数 | M9: ='【4月】月間進捗管理シート'!X10 -> 941 | N9: アポ→通過 | O9: 17 | Q9: 現状コール数 | S9: アポ→通過 | V9: 現状コール数 | X9: アポ→通過
B10: 1週間の平均受注数 | D10: ='【4月】月間進捗管理シート'!I11 -> 0 | G10: 1週間の平均受注数 | I10: ='【4月】月間進捗管理シート'!Q11 -> 0 | L10: 1週間の平均受注数 | N10: ='【4月】月間進捗管理シート'!X11 -> 0.66666667 | Q10: 1週間の平均受注数 | V10: 1週間の平均受注数
B11: 1週間の平均消化数 | D11: ='【4月】月間進捗管理シート'!I12 -> 0.66666667 | G11: 1週間の平均消化数 | I11: ='【4月】月間進捗管理シート'!Q12 -> 1.3333333 | L11: 1週間の平均消化数 | N11: ='【4月】月間進捗管理シート'!X12 -> 2 | Q11: 1週間の平均消化数 | V11: 1週間の平均消化数
B12: 1週間の平均アポ数 | D12: ='【4月】月間進捗管理シート'!I13 -> 3.3333333 | G12: 1週間の平均アポ数 | I12: ='【4月】月間進捗管理シート'!Q13 -> 2.1666667 | L12: 1週間の平均アポ数 | N12: ='【4月】月間進捗管理シート'!X13 -> 1.5 | Q12: 1週間の平均アポ数 | V12: 1週間の平均アポ数
B13: 1週間の平均コール数 | D13: ='【4月】月間進捗管理シート'!I14 -> 216 | G13: 1週間の平均コール数 | I13: ='【4月】月間進捗管理シート'!Q14 -> 183.16667 | L13: 1週間の平均コール数 | N13: ='【4月】月間進捗管理シート'!X14 -> 156.83333 | Q13: 1週間の平均コール数 | V13: 1週間の平均コール数
A15: 縞谷 | B15: 45749 | C15: ~ | E15: 45751 | G15: 45754 | H15: ~ | J15: 45759 | L15: 45761 | M15: ~ | O15: 45766 | Q15: 45768 | R15: ~ | T15: 45773 | V15: 45775 | W15: ~ | Y15: 45777
B16: 売上 | C16: ='【4月】月間進捗管理シート'!I18 -> 0 | D16: 平均単価 | E16: =C16/C17 -> #DIV/0! | G16: 売上 | H16: ='【4月】月間進捗管理シート'!Q18 -> 0 | I16: 平均単価 | J16: =H16/H17 -> #DIV/0! | L16: 売上 | M16: ='【4月】月間進捗管理シート'!X18 -> 885000 | N16: 平均単価 | O16: =M16/M17 -> 221250 | Q16: 売上 | S16: 平均単価 | T16: =R16/R17 -> #DIV/0! | V16: 売上 | X16: 平均単価 | Y16: =W16/W17 -> #DIV/0!
B17: 受注数 | C17: ='【4月】月間進捗管理シート'!I19 -> 0 | D17: 現状受注率 | E17: =C18/C17 -> #DIV/0! | G17: 受注数 | H17: ='【4月】月間進捗管理シート'!Q19 -> 0 | I17: 現状受注率 | J17: =H18/H17 -> #DIV/0! | L17: 受注数 | M17: ='【4月】月間進捗管理シート'!X19 -> 4 | N17: 現状受注率 | O17: =M18/M17 -> 2.5 | Q17: 受注数 | S17: 現状受注率 | T17: =R18/R17 -> #DIV/0! | V17: 受注数 | X17: 現状受注率 | Y17: =W18/W17 -> #DIV/0!
B18: 有効商談数 | C18: ='【4月】月間進捗管理シート'!I20 -> 2 | D18: 現状出席率 | E18: =C18/C20 -> 0.66666667 | G18: 有効商談数 | H18: ='【4月】月間進捗管理シート'!Q20 -> 8 | I18: 現状出席率 | J18: =H18/H20 -> 0.57142857 | L18: 有効商談数 | M18: ='【4月】月間進捗管理シート'!X20 -> 10 | N18: 現状出席率 | O18: =M18/M20 -> 0.76923077 | Q18: 有効商談数 | S18: 現状出席率 | T18: =R18/R20 -> #DIV/0! | V18: 有効商談数 | X18: 現状出席率 | Y18: =W18/W20 -> #DIV/0!
B19: 無効商談数 | C19: ='【4月】月間進捗管理シート'!I21 -> 0 | D19: 現状アポ転換率 | E19: =C21/C22 -> 0.039473684 | G19: 無効商談数 | H19: ='【4月】月間進捗管理シート'!Q21 -> 0 | I19: 現状アポ転換率 | J19: =H21/H22 -> 0.013921114 | L19: 無効商談数 | M19: ='【4月】月間進捗管理シート'!X21 -> 0 | N19: 現状アポ転換率 | O19: =M21/M22 -> 0.017361111 | Q19: 無効商談数 | S19: 現状アポ転換率 | T19: =R21/R22 -> #DIV/0! | V19: 無効商談数 | X19: 現状アポ転換率 | Y19: =W21/W22 -> #DIV/0!
B20: 新規商談予定 | C20: ='【4月】月間進捗管理シート'!I22 -> 3 | D20: アポ→商談 | G20: 新規商談予定 | H20: ='【4月】月間進捗管理シート'!Q22 -> 14 | I20: アポ→商談 | L20: 新規商談予定 | M20: ='【4月】月間進捗管理シート'!X22 -> 13 | N20: アポ→商談 | Q20: 新規商談予定 | S20: アポ→商談 | V20: 新規商談予定 | X20: アポ→商談
B21: 現状アポ数 | C21: ='【4月】月間進捗管理シート'!I24 -> 9 | D21: アポ→受注 | G21: 現状アポ数 | H21: ='【4月】月間進捗管理シート'!Q24 -> 6 | I21: アポ→受注 | L21: 現状アポ数 | M21: ='【4月】月間進捗管理シート'!X24 -> 5 | N21: アポ→受注 | Q21: 現状アポ数 | S21: アポ→受注 | V21: 現状アポ数 | X21: アポ→受注
B22: 現状コール数 | C22: ='【4月】月間進捗管理シート'!I25 -> 228 | D22: アポ→通過 | G22: 現状コール数 | H22: ='【4月】月間進捗管理シート'!Q25 -> 431 | I22: アポ→通過 | L22: 現状コール数 | M22: ='【4月】月間進捗管理シート'!X25 -> 288 | N22: アポ→通過 | Q22: 現状コール数 | S22: アポ→通過 | V22: 現状コール数 | X22: アポ→通過
B23: 1週間の平均受注数 | D23: ='【4月】月間進捗管理シート'!I26 -> 0 | G23: 1週間の平均受注数 | I23: ='【4月】月間進捗管理シート'!Q26 -> 0 | L23: 1週間の平均受注数 | N23: ='【4月】月間進捗管理シート'!X26 -> 0.66666667 | Q23: 1週間の平均受注数 | V23: 1週間の平均受注数
B24: 1週間の平均消化数 | D24: ='【4月】月間進捗管理シート'!I27 -> 0.66666667 | G24: 1週間の平均消化数 | I24: ='【4月】月間進捗管理シート'!Q27 -> 1.3333333 | L24: 1週間の平均消化数 | N24: ='【4月】月間進捗管理シート'!X27 -> 1.6666667 | Q24: 1週間の平均消化数 | V24: 1週間の平均消化数
B25: 1週間の平均アポ数 | D25: ='【4月】月間進捗管理シート'!I28 -> 3 | G25: 1週間の平均アポ数 | I25: ='【4月】月間進捗管理シート'!Q28 -> 1 | L25: 1週間の平均アポ数 | N25: ='【4月】月間進捗管理シート'!X28 -> 0.83333333 | Q25: 1週間の平均アポ数 | V25: 1週間の平均アポ数
B26: 1週間の平均コール数 | D26: ='【4月】月間進捗管理シート'!I29 -> 76 | G26: 1週間の平均コール数 | I26: ='【4月】月間進捗管理シート'!Q29 -> 71.833333 | L26: 1週間の平均コール数 | N26: ='【4月】月間進捗管理シート'!X29 -> 48 | Q26: 1週間の平均コール数 | V26: 1週間の平均コール数
A28: 前川 | B28: 45749 | C28: ~ | E28: 45751 | G28: 45754 | H28: ~ | J28: 45759 | L28: 45761 | M28: ~ | O28: 45766 | Q28: 45768 | R28: ~ | T28: 45773 | V28: 45775 | W28: ~ | Y28: 45777
B29: 売上 | C29: ='【4月】月間進捗管理シート'!I33 -> 0 | D29: 平均単価 | E29: =C29/C30 -> #DIV/0! | G29: 売上 | H29: ='【4月】月間進捗管理シート'!Q33 -> 0 | I29: 平均単価 | J29: =H29/H30 -> #DIV/0! | L29: 売上 | M29: ='【4月】月間進捗管理シート'!X33 -> 0 | N29: 平均単価 | O29: =M29/M30 -> #DIV/0! | Q29: 売上 | S29: 平均単価 | T29: =R29/R30 -> #DIV/0! | V29: 売上 | X29: 平均単価 | Y29: =W29/W30 -> #DIV/0!
B30: 受注数 | C30: ='【4月】月間進捗管理シート'!I34 -> 0 | D30: 現状受注率 | E30: =C31/C30 -> #DIV/0! | G30: 受注数 | H30: ='【4月】月間進捗管理シート'!Q34 -> 0 | I30: 現状受注率 | J30: =H31/H30 -> #DIV/0! | L30: 受注数 | M30: ='【4月】月間進捗管理シート'!X34 -> 0 | N30: 現状受注率 | O30: =M31/M30 -> #DIV/0! | Q30: 受注数 | S30: 現状受注率 | T30: =R31/R30 -> #DIV/0! | V30: 受注数 | X30: 現状受注率 | Y30: =W31/W30 -> #DIV/0!
B31: 有効商談数 | C31: ='【4月】月間進捗管理シート'!I35 -> 0 | D31: 現状出席率 | E31: =C31/C33 -> 0 | G31: 有効商談数 | H31: ='【4月】月間進捗管理シート'!Q35 -> 0 | I31: 現状出席率 | J31: =H31/H33 -> #DIV/0! | L31: 有効商談数 | M31: ='【4月】月間進捗管理シート'!X35 -> 2 | N31: 現状出席率 | O31: =M31/M33 -> 0.66666667 | Q31: 有効商談数 | S31: 現状出席率 | T31: =R31/R33 -> #DIV/0! | V31: 有効商談数 | X31: 現状出席率 | Y31: =W31/W33 -> #DIV/0!
B32: 無効商談数 | C32: ='【4月】月間進捗管理シート'!I36 -> 0 | D32: 現状アポ転換率 | E32: =C34/C35 -> 0.0023809524 | G32: 無効商談数 | H32: ='【4月】月間進捗管理シート'!Q36 -> 0 | I32: 現状アポ転換率 | J32: =H34/H35 -> 0.010479042 | L32: 無効商談数 | M32: ='【4月】月間進捗管理シート'!X36 -> 0 | N32: 現状アポ転換率 | O32: =M34/M35 -> 0.0061255743 | Q32: 無効商談数 | S32: 現状アポ転換率 | T32: =R34/R35 -> #DIV/0! | V32: 無効商談数 | X32: 現状アポ転換率 | Y32: =W34/W35 -> #DIV/0!
B33: 新規商談予定 | C33: ='【4月】月間進捗管理シート'!I37 -> 1 | D33: アポ→商談 | G33: 新規商談予定 | H33: ='【4月】月間進捗管理シート'!Q37 -> 0 | I33: アポ→商談 | L33: 新規商談予定 | M33: ='【4月】月間進捗管理シート'!X37 -> 3 | N33: アポ→商談 | Q33: 新規商談予定 | S33: アポ→商談 | V33: 新規商談予定 | X33: アポ→商談
B34: 現状アポ数 | C34: ='【4月】月間進捗管理シート'!I39 -> 1 | D34: アポ→受注 | G34: 現状アポ数 | H34: ='【4月】月間進捗管理シート'!Q39 -> 7 | I34: アポ→受注 | L34: 現状アポ数 | M34: ='【4月】月間進捗管理シート'!X39 -> 4 | N34: アポ→受注 | Q34: 現状アポ数 | S34: アポ→受注 | V34: 現状アポ数 | X34: アポ→受注
B35: 現状コール数 | C35: ='【4月】月間進捗管理シート'!I40 -> 420 | D35: アポ→通過 | G35: 現状コール数 | H35: ='【4月】月間進捗管理シート'!Q40 -> 668 | I35: アポ→通過 | L35: 現状コール数 | M35: ='【4月】月間進捗管理シート'!X40 -> 653 | N35: アポ→通過 | Q35: 現状コール数 | S35: アポ→通過 | V35: 現状コール数 | X35: アポ→通過
B36: 1週間の平均受注数 | D36: ='【4月】月間進捗管理シート'!I41 -> 0 | G36: 1週間の平均受注数 | I36: ='【4月】月間進捗管理シート'!Q41 -> 0 | L36: 1週間の平均受注数 | N36: ='【4月】月間進捗管理シート'!X41 -> 0 | Q36: 1週間の平均受注数 | V36: 1週間の平均受注数
B37: 1週間の平均消化数 | D37: ='【4月】月間進捗管理シート'!I42 -> 0 | G37: 1週間の平均消化数 | I37: ='【4月】月間進捗管理シート'!Q42 -> 0 | L37: 1週間の平均消化数 | N37: ='【4月】月間進捗管理シート'!X42 -> 0.33333333 | Q37: 1週間の平均消化数 | V37: 1週間の平均消化数
B38: 1週間の平均アポ数 | D38: ='【4月】月間進捗管理シート'!I43 -> 0.33333333 | G38: 1週間の平均アポ数 | I38: ='【4月】月間進捗管理シート'!Q43 -> 1.1666667 | L38: 1週間の平均アポ数 | N38: ='【4月】月間進捗管理シート'!X43 -> 0.66666667 | Q38: 1週間の平均アポ数 | V38: 1週間の平均アポ数
B39: 1週間の平均コール数 | D39: ='【4月】月間進捗管理シート'!I44 -> 140 | G39: 1週間の平均コール数 | I39: ='【4月】月間進捗管理シート'!Q44 -> 111.33333 | L39: 1週間の平均コール数 | N39: ='【4月】月間進捗管理シート'!X44 -> 108.83333 | Q39: 1週間の平均コール数 | V39: 1週間の平均コール数

Sheet 【5月】月間進捗管理シート
A1: 全体 | B1: 計画値 | D1: 現状 | E1: 水 | F1: 木 | G1: 金 | H1: 土 | I1: 日 | J1: 月 | K1: 火 | L1: 水 | M1: 木 | N1: 金 | O1: 土 | P1: 日 | Q1: 月 | R1: 火 | S1: 水 | T1: 木 | U1: 金 | V1: 土 | W1: 日 | X1: 月 | Y1: 火 | Z1: 水 | AA1: 木 | AB1: 金 | AC1: 土 | AD1: 日
E2: 45784 | F2: 45785 | G2: 45786 | H2: 45787 | I2: 45788 | J2: 45789 | K2: 45790 | L2: 45791 | M2: 45792 | N2: 45793 | O2: 45794 | P2: 45795 | Q2: 45796 | R2: 45797 | S2: 45798 | T2: 45799 | U2: 45800 | V2: 45801 | W2: 45802 | X2: 45803 | Y2: 45804 | Z2: 45805 | AA2: 45806 | AB2: 45807 | AC2: 45808
A3: 売上目標 | B3: =B19+B34 -> 2800000 | C3: 現状売上 | D3: =#REF!+P3+W3+AD3 -> #REF! | E3: =E19+E34 -> 0 | F3: =F19+F34 -> 0 | G3: =G19+G34 -> 0 | H3: =H19+H34 -> 0 | I3: =sum(E3:H3) -> 0 | J3: =J19+J34 -> 0 | K3: =K19+K34 -> 0 | L3: =L19+L34 -> 0 | M3: =M19+M34 -> 0 | N3: =N19+N34 -> 0 | O3: =O19+O34 -> 1 | P3: =sum(J3:O3) -> 1 | Q3: =Q19+Q34 -> 0 | R3: =R19+R34 -> 0 | S3: =S19+S34 -> 0 | T3: =T19+T34 -> 0 | U3: =U19+U34 -> 0 | V3: =V19+V34 -> 0 | W3: =sum(Q3:V3) -> 0 | X3: =X19+X34 -> 0 | Y3: =Y19+Y34 -> 0 | Z3: =Z19+Z34 -> 0 | AA3: =AA19+AA34 -> 0 | AB3: =AB19+AB34 -> 0 | AC3: =AC19+AC34 -> 0 | AD3: =sum(X3:AC3) -> 0
A4: 目標受注数 | B4: =B20+B35 -> 14 | C4: 現状受注数 | D4: =H4+P4+W4+AD4 -> 120000 | E4: =E20+E35 -> 0 | F4: =F20+F35 -> 0 | G4: =G20+G36 -> 1 | H4: =H20+H35 -> 0 | I4: =SUM(C4:H4) -> 120001 | J4: =J20+J35 -> 0 | K4: =K20+K35 -> 0 | L4: =L20+L35 -> 0 | M4: =M20+M35 -> 0 | N4: =N20+N35 -> 0 | O4: =O20+O35 -> 120000 | P4: =SUM(J4:O4) -> 120000 | Q4: =Q20+Q35 -> 0 | R4: =R20+R35 -> 0 | S4: =S20+S35 -> 0 | T4: =T20+T35 -> 0 | U4: =U20+U35 -> 0 | V4: =V20+V35 -> 0 | W4: =sum(Q4:V4) -> 0 | X4: =X20+X35 -> 0 | Y4: =Y20+Y35 -> 0 | Z4: =Z20+Z35 -> 0 | AA4: =AA20+AA35 -> 0 | AB4: =AB20+AB35 -> 0 | AC4: =AC20+AC35 -> 0 | AD4: =sum(X4:AC4) -> 0
A5: 目標有効商談数 | B5: =B4/B8 -> 56 | C5: 現状有効商談数 | D5: =H5+P5+W5+AD5 -> 16 | E5: =E21+E36 -> 2 | F5: =F21+F36 -> 2 | G5: =G21+G37 -> 1 | H5: =H21+H36 -> 2 | I5: =SUM(C5:H5) -> 23 | J5: =J21+J36 -> 0 | K5: =K21+K36 -> 0 | L5: =L21+L36 -> 1 | M5: =M21+M36 -> 2 | N5: =N21+N36 -> 1 | O5: =O21+O36 -> 3 | P5: =SUM(J5:O5) -> 7 | Q5: =Q21+Q36 -> 2 | R5: =R21+R36 -> 1 | S5: =S21+S36 -> 1 | T5: =T21+T36 -> 2 | U5: =U21+U36 -> 1 | V5: =V21+V36 -> 0 | W5: =sum(Q5:V5) -> 7 | X5: =X21+X36 -> 0 | Y5: =Y21+Y36 -> 0 | Z5: =Z21+Z36 -> 0 | AA5: =AA21+AA36 -> 0 | AB5: =AB21+AB36 -> 0 | AC5: =AC21+AC36 -> 0 | AD5: =sum(X5:AC5) -> 0
A6: 目標アポ数 | B6: =B5/B9 -> 80 | C6: 現状無効商談数 | D6: =H6+P6+W6+AD6 -> 0 | E6: =E22+E37 -> 0 | F6: =F22+F37 -> 0 | G6: =G22+#REF! -> #REF! | H6: =H22+H37 -> 0 | I6: =SUM(C6:H6) -> #REF! | J6: =J22+J37 -> 0 | K6: =K22+K37 -> 0 | L6: =L22+L37 -> 0 | M6: =M22+M37 -> 0 | N6: =N22+N37 -> 0 | O6: =O22+O37 -> 0 | P6: =SUM(J6:O6) -> 0 | Q6: =Q22+Q37 -> 0 | R6: =R22+R37 -> 0 | S6: =S22+S37 -> 0 | T6: =T22+T37 -> 0 | U6: =U22+U37 -> 0 | V6: =V22+V37 -> 0 | W6: =sum(Q6:V6) -> 0 | X6: =X22+X37 -> 0 | Y6: =Y22+Y37 -> 0 | Z6: =Z22+Z37 -> 0 | AA6: =AA22+AA37 -> 0 | AB6: =AB22+AB37 -> 0 | AC6: =AC22+AC37 -> 0 | AD6: =sum(X6:AC6) -> 0
A7: 目標コール数 | B7: =B6/B10 -> 4000 | C7: 新規商談予定 | D7: =H7+P7+W7+AD7 -> 31 | E7: =E23+E38 -> 2 | F7: =F23+F38 -> 3 | G7: =G23+G38 -> 2 | H7: =H23+H38 -> 2 | I7: =SUM(C7:H7) -> 40 | J7: =J23+J38 -> 2 | K7: =K23+K38 -> 0 | L7: =L23+L38 -> 2 | M7: =M23+M38 -> 4 | N7: =N23+N38 -> 2 | O7: =O23+O38 -> 3 | P7: =SUM(J7:O7) -> 13 | Q7: =Q23+Q38 -> 4 | R7: =R23+R38 -> 4 | S7: =S23+S38 -> 1 | T7: =T23+T38 -> 3 | U7: =U23+U38 -> 2 | V7: =V23+V38 -> 0 | W7: =sum(Q7:V7) -> 14 | X7: =X23+X38 -> 2 | Y7: =Y23+Y38 -> 0 | Z7: =Z23+Z38 -> 0 | AA7: =AA23+AA38 -> 0 | AB7: =AB23+AB38 -> 0 | AC7: =AC23+AC38 -> 0 | AD7: =sum(X7:AC7) -> 2
A8: 目標受注率 | B8: 0.25 | C8: 当日アポ目標 | D8: =H8+P8+W8+AD8 -> 40 | E8: =E24+E39 -> 4 | F8: =F24+F39 -> 5 | G8: =G24+G39 -> 5 | H8: =H24+H39 -> 5 | I8: =SUM(C8:H8) -> 59 | J8: =J24+J39 -> 6 | K8: =K24+K39 -> 5 | L8: =L24+L39 -> 5 | M8: =M24+M39 -> 5 | N8: =N24+N39 -> 3 | O8: =O24+O39 -> 3 | P8: =SUM(J8:O8) -> 27 | Q8: =Q24+Q39 -> 0 | R8: =R24+R39 -> 2 | S8: =S24+S39 -> 1 | T8: =T24+T39 -> 1 | U8: =U24+U39 -> 1 | V8: =V24+V39 -> 0 | W8: =sum(Q8:V8) -> 5 | X8: =X24+X39 -> 1 | Y8: =Y24+Y39 -> 2 | Z8: =Z24+Z39 -> 0 | AA8: =AA24+AA39 -> 0 | AB8: =AB24+AB39 -> 0 | AC8: =AC24+AC39 -> 0 | AD8: =sum(X8:AC8) -> 3
A9: 目標出席率 | B9: 0.7 | C9: 現状アポ数 | D9: =H9+P9+W9+AD9 -> 20 | E9: =E25+E40 -> 1 | F9: =F25+F40 -> 3 | G9: =G25+G40 -> 1 | H9: =H25+H40 -> 1 | I9: =SUM(C9:H9) -> 26 | J9: =J25+J40 -> 2 | K9: =K25+K40 -> 2 | L9: =L25+L40 -> 3 | M9: =M25+M40 -> 1 | N9: =N25+N40 -> 4 | O9: =O25+O40 -> 2 | P9: =SUM(J9:O9) -> 14 | Q9: =Q25+Q40 -> 0 | R9: =R25+R40 -> 1 | S9: =S25+S40 -> 2 | T9: =T25+T40 -> 1 | U9: =U25+U40 -> 1 | V9: =V25+V40 -> 0 | W9: =sum(Q9:V9) -> 5 | X9: =X25+X40 -> 0 | Y9: =Y25+Y40 -> 0 | Z9: =Z25+Z40 -> 0 | AA9: =AA25+AA40 -> 0 | AB9: =AB25+AB40 -> 0 | AC9: =AC25+AC40 -> 0 | AD9: =sum(X9:AC9) -> 0
A10: 目標アポ転換率 | B10: 0.02 | C10: 現状コール数 | D10: =H10+P10+W10+AD10 -> 2300 | E10: =E26+E41 -> 161 | F10: =F26+F41 -> 231 | G10: =G26+G41 -> 261 | H10: =H26+H41 -> 249 | I10: =SUM(C10:H10) -> 3202 | J10: =J26+J41 -> 229 | K10: =K26+K41 -> 109 | L10: =L26+L41 -> 170 | M10: =M26+M41 -> 147 | N10: =N26+N41 -> 217 | O10: =O26+O41 -> 239 | P10: =SUM(J10:O10) -> 1111 | Q10: =Q26+Q41 -> 194 | R10: =R26+R41 -> 155 | S10: =S26+S41 -> 190 | T10: =T26+T41 -> 134 | U10: =U26+U41 -> 6 | V10: =V26+V41 -> 0 | W10: =sum(Q10:V10) -> 679 | X10: =X26+X41 -> 121 | Y10: =Y26+Y41 -> 140 | Z10: =Z26+Z41 -> 0 | AA10: =AA26+AA41 -> 0 | AB10: =AB26+AB41 -> 0 | AC10: =AC26+AC41 -> 0 | AD10: =sum(X10:AC10) -> 261
A11: 1日の平均受注数 | B11: =D4/日にち -> #NAME? | C11: 現状受注率 | D11: =D4/sum(D5:D6) -> 7500 | E11: 1週間の平均受注数 | I11: =I4/4 -> 30000.25 | J11: 1週間の平均受注数 | P11: =P4/6 -> 20000 | Q11: 1週間の平均受注数 | W11: =W4/6 -> 0 | X11: 1週間の平均受注数 | AD11: =AD4/6 -> 0
A12: 1日の平均消化数 | B12: =D5/日にち -> #NAME? | C12: 現状出席率 | D12: =sum(D5:D6)/D7 -> 0.51612903 | E12: 1週間の平均消化数 | I12: =I5/4 -> 5.75 | J12: 1週間の平均消化数 | P12: =P5/6 -> 1.1666667 | Q12: 1週間の平均消化数 | W12: =W5/6 -> 1.1666667 | X12: 1週間の平均消化数 | AD12: =AD5/6 -> 0
A13: 1日の平均アポ数 | B13: =D9/日にち -> #NAME? | C13: 現状商談転換率 | D13: =SUM(D5:D6)/D9 -> 0.8 | E13: 1週間の平均アポ数 | I13: =I9/4 -> 6.5 | J13: 1週間の平均アポ数 | P13: =P9/6 -> 2.3333333 | Q13: 1週間の平均アポ数 | W13: =W9/6 -> 0.83333333 | X13: 1週間の平均アポ数 | AD13: =AD9/6 -> 0
A14: 1日の平均コール数 | B14: =D10/日にち -> #NAME? | C14: 現状アポ転換率 | D14: =D9/D10 -> 0.0086956522 | E14: 1週間の平均コール数 | I14: =I10/4 -> 800.5 | J14: 1週間の平均コール数 | P14: =P10/6 -> 185.16667 | Q14: 1週間の平均コール数 | W14: =W10/6 -> 113.16667 | X14: 1週間の平均コール数 | AD14: =AD10/6 -> 43.5
A17: 縞谷 | B17: 計画値 | D17: 現状 | E17: 水 | F17: 木 | G17: 金 | H17: 土 | I17: 日 | J17: 月 | K17: 火 | L17: 水 | M17: 木 | N17: 金 | O17: 土 | P17: 日 | Q17: 月 | R17: 火 | S17: 水 | T17: 木 | U17: 金 | V17: 土 | W17: 日 | X17: 月 | Y17: 火 | Z17: 水 | AA17: 木 | AB17: 金 | AC17: 土 | AD17: 日
E18: 45784 | F18: 45785 | G18: 45786 | H18: 45787 | I18: 45788 | J18: 45789 | K18: 45790 | L18: 45791 | M18: 45792 | N18: 45793 | O18: 45794 | P18: 45795 | Q18: 45796 | R18: 45797 | S18: 45798 | T18: 45799 | U18: 45800 | V18: 45801 | W18: 45802 | X18: 45803 | Y18: 45804 | Z18: 45805 | AA18: 45806 | AB18: 45807 | AC18: 45808
A19: 売上目標 | B19: 1800000 | C19: 現状売上 | D19: =I19+P19+W19+AD19 -> 1 | I19: =sum(E19:H19) -> 0 | O19: 1 | P19: =sum(J19:O19) -> 1 | W19: =sum(Q19:V19) -> 0 | AD19: =sum(X19:AC19) -> 0
A20: 目標受注数 | B20: 9 | C20: 現状受注数 | D20: =I20+P20+W20+AD20 -> 120000 | I20: =sum(E20:H20) -> 0 | O20: 120000 | P20: =SUM(J20:O20) -> 120000 | W20: =sum(Q20:V20) -> 0 | AD20: =sum(X20:AC20) -> 0
A21: 目標有効商談数 | B21: =B20/B24 -> 36 | C21: 現状有効商談数 | D21: =I21+P21+W21+AD21 -> 16 | E21: 2 | F21: 2 | G21: 1 | H21: 1 | I21: =sum(E21:H21) -> 6 | M21: 1 | N21: 1 | O21: 2 | P21: =SUM(J21:O21) -> 4 | Q21: 1 | R21: 1 | S21: 1 | T21: 2 | U21: 1 | W21: =sum(Q21:V21) -> 6 | AD21: =sum(X21:AC21) -> 0
A22: 目標アポ数 | B22: =B21/B25 -> 51.428571 | C22: 現状無効商談数 | D22: =I22+P22+W22+AD22 -> 0 | I22: =sum(E22:H22) -> 0 | P22: =SUM(J22:O22) -> 0 | W22: =sum(Q22:V22) -> 0 | AD22: =sum(X22:AC22) -> 0
A23: 目標コール数 | B23: =B22/B26 -> 3428.5714 | C23: 新規商談予定 | D23: =I23+P23+W23+AD23 -> 29 | E23: 2 | F23: 3 | G23: 1 | H23: 1 | I23: =sum(E23:H23) -> 7 | J23: 1 | L23: 1 | M23: 3 | N23: 2 | O23: 2 | P23: =SUM(J23:O23) -> 9 | Q23: 3 | R23: 4 | S23: 1 | T23: 3 | U23: 2 | W23: =sum(Q23:V23) -> 13 | AD23: =sum(X23:AC23) -> 0
A24: 目標受注率 | B24: 0.25 | C24: 当日アポ目標 | D24: =I24+P24+W24+AD24 -> 20 | E24: 2 | F24: 3 | G24: 3 | H24: 3 | I24: =sum(E24:H24) -> 11 | J24: 3 | K24: 2 | L24: 2 | M24: 2 | P24: =SUM(J24:O24) -> 9 | W24: =sum(Q24:V24) -> 0 | AD24: =sum(X24:AC24) -> 0
A25: 目標出席率 | B25: 0.7 | C25: 現状アポ数 | D25: =I25+P25+W25+AD25 -> 17 | E25: 1 | F25: 1 | G25: 0 | H25: 1 | I25: =sum(E25:H25) -> 3 | J25: 1 | K25: 1 | L25: 3 | M25: 0 | N25: 3 | O25: 2 | P25: =SUM(J25:O25) -> 10 | Q25: 0 | R25: 1 | S25: 2 | T25: 1 | W25: =sum(Q25:V25) -> 4 | AD25: =sum(X25:AC25) -> 0
A26: 目標アポ転換率 | B26: 0.015 | C26: 現状コール数 | D26: =I26+P26+W26+AD26 -> 827 | E26: 31 | F26: 59 | G26: 101 | H26: 100 | I26: =sum(E26:H26) -> 291 | J26: 82 | K26: 34 | L26: 60 | M26: 55 | N26: 66 | O26: 77 | P26: =SUM(J26:O26) -> 374 | Q26: 52 | R26: 11 | S26: 82 | T26: 17 | W26: =sum(Q26:V26) -> 162 | AD26: =sum(X26:AC26) -> 0
A27: 1日の平均受注数 | B27: =D20/'【第一】案件管理シート'!E2 -> 8000 | C27: 現状受注率 | D27: =D20/sum(D21:D22) -> 7500 | E27: 1週間の平均受注数 | I27: =I20/4 -> 0 | J27: 1週間の平均受注数 | P27: =P20/6 -> 20000 | Q27: 1週間の平均受注数 | W27: =W20/6 -> 0 | X27: 1週間の平均受注数 | AD27: =AD20/6 -> 0
A28: 1日の平均消化数 | B28: =D21/'【第一】案件管理シート'!E2 -> 1.0666667 | C28: 現状出席率 | D28: =sum(D21:D22)/D23 -> 0.55172414 | E28: 1週間の平均消化数 | I28: =I21/4 -> 1.5 | J28: 1週間の平均消化数 | P28: =P21/6 -> 0.66666667 | Q28: 1週間の平均消化数 | W28: =W21/6 -> 1 | X28: 1週間の平均消化数 | AD28: =AD21/6 -> 0
A29: 1日の平均アポ数 | B29: =D25/'【第一】案件管理シート'!E2 -> 1.1333333 | C29: 現状商談転換率 | D29: =SUM(D21:D22)/D25 -> 0.94117647 | E29: 1週間の平均アポ数 | I29: =I25/4 -> 0.75 | J29: 1週間の平均アポ数 | P29: =P25/6 -> 1.6666667 | Q29: 1週間の平均アポ数 | W29: =W25/6 -> 0.66666667 | X29: 1週間の平均アポ数 | AD29: =AD25/6 -> 0
A30: 1日の平均コール数 | B30: =D26/'【第一】案件管理シート'!E2 -> 55.133333 | C30: 現状アポ転換率 | D30: =D25/D26 -> 0.020556227 | E30: 1週間の平均コール数 | I30: =I26/4 -> 72.75 | J30: 1週間の平均コール数 | P30: =P26/6 -> 62.333333 | Q30: 1週間の平均コール数 | W30: =W26/6 -> 27 | X30: 1週間の平均コール数 | AD30: =AD26/6 -> 0
A32: 前川 | B32: 計画値 | D32: 現状 | E32: 水 | F32: 木 | G32: 金 | H32: 土 | I32: 日 | J32: 月 | K32: 火 | L32: 水 | M32: 木 | N32: 金 | O32: 土 | P32: 日 | Q32: 月 | R32: 火 | S32: 水 | T32: 木 | U32: 金 | V32: 土 | W32: 日 | X32: 月 | Y32: 火 | Z32: 水 | AA32: 木 | AB32: 金 | AC32: 土 | AD32: 日
E33: 45784 | F33: 45785 | G33: 45786 | H33: 45787 | I33: 45788 | J33: 45789 | K33: 45790 | L33: 45791 | M33: 45792 | N33: 45793 | O33: 45794 | P33: 45795 | Q33: 45796 | R33: 45797 | S33: 45798 | T33: 45799 | U33: 45800 | V33: 45801 | W33: 45802 | X33: 45803 | Y33: 45804 | Z33: 45805 | AA33: 45806 | AB33: 45807 | AC33: 45808
A34: 売上目標 | B34: 1000000 | C34: 現状売上 | D34: =I34+P34+W34+AD34 -> 0 | I34: =sum(E34:H34) -> 0 | P34: =sum(J34:O34) -> 0 | W34: =sum(Q34:V34) -> 0 | AD34: =sum(X34:AC34) -> 0
A35: 目標受注数 | B35: 5 | C35: 現状受注数 | D35: =I35+P35+W35+AD35 -> 0 | I35: =sum(E35:H35) -> 0 | P35: =SUM(J35:O35) -> 0 | W35: =sum(Q35:V35) -> 0 | AD35: =sum(X35:AC35) -> 0
A36: 目標有効商談数 | B36: =B35/B39 -> 25 | C36: 現状有効商談数 | D36: =I36+P36+W36+AD36 -> 6 | G36: 1 | H36: 1 | I36: =sum(E36:H36) -> 2 | L36: 1 | M36: 1 | O36: 1 | P36: =SUM(J36:O36) -> 3 | Q36: 1 | W36: =sum(Q36:V36) -> 1 | AD36: =sum(X36:AC36) -> 0
A37: 目標アポ数 | B37: =B36/B40 -> 35.714286 | C37: 現状無効商談数 | D37: =I37+P37+W37+AD37 -> 0 | I37: =sum(E37:H37) -> 0 | P37: =SUM(J37:O37) -> 0 | W37: =sum(Q37:V37) -> 0 | AD37: =sum(X37:AC37) -> 0
A38: 目標コール数 | B38: =B37/B41 -> 2380.9524 | C38: 新規商談予定 | D38: =I38+P38+W38+AD38 -> 9 | G38: 1 | H38: 1 | I38: =sum(E38:H38) -> 2 | J38: 1 | L38: 1 | M38: 1 | O38: 1 | P38: =SUM(J38:O38) -> 4 | Q38: 1 | W38: =sum(Q38:V38) -> 1 | X38: 2 | AD38: =sum(X38:AC38) -> 2
A39: 目標受注率 | B39: 0.2 | C39: 当日アポ目標 | D39: =I39+P39+W39+AD39 -> 34 | E39: 2 | F39: 2 | G39: 2 | H39: 2 | I39: =sum(E39:H39) -> 8 | J39: 3 | K39: 3 | L39: 3 | M39: 3 | N39: 3 | O39: 3 | P39: =SUM(J39:O39) -> 18 | R39: 2 | S39: 1 | T39: 1 | U39: 1 | W39: =sum(Q39:V39) -> 5 | X39: 1 | Y39: 2 | AD39: =sum(X39:AC39) -> 3
A40: 目標出席率 | B40: 0.7 | C40: 現状アポ数 | D40: =I40+P40+W40+AD40 -> 8 | E40: 0 | F40: 2 | G40: 1 | H40: 0 | I40: =sum(E40:H40) -> 3 | J40: 1 | K40: 1 | L40: 0 | M40: 1 | N40: 1 | O40: 0 | P40: =SUM(J40:O40) -> 4 | Q40: 0 | R40: 0 | S40: 0 | T40: 0 | U40: 1 | W40: =sum(Q40:V40) -> 1 | X40: 0 | Y40: 0 | AD40: =sum(X40:AC40) -> 0
A41: 目標アポ転換率 | B41: 0.015 | C41: 現状コール数 | D41: =I41+P41+W41+AD41 -> 2126 | E41: 130 | F41: 172 | G41: 160 | H41: 149 | I41: =sum(E41:H41) -> 611 | J41: 147 | K41: 75 | L41: 110 | M41: 92 | N41: 151 | O41: 162 | P41: =SUM(J41:O41) -> 737 | Q41: 142 | R41: 144 | S41: 108 | T41: 117 | U41: 6 | W41: =sum(Q41:V41) -> 517 | X41: 121 | Y41: 140 | AD41: =sum(X41:AC41) -> 261
A42: 1日の平均受注数 | B42: =D35/'【第一】案件管理シート'!E2 -> 0 | C42: 現状受注率 | D42: =D35/sum(D36:D37) -> 0 | E42: 1週間の平均受注数 | I42: =I35/4 -> 0 | J42: 1週間の平均受注数 | P42: =P35/6 -> 0 | Q42: 1週間の平均受注数 | W42: =W35/6 -> 0 | X42: 1週間の平均受注数 | AD42: =AD35/6 -> 0
A43: 1日の平均消化数 | B43: =D36/'【第一】案件管理シート'!E2 -> 0.4 | C43: 現状出席率 | D43: =sum(D36:D37)/D38 -> 0.66666667 | E43: 1週間の平均消化数 | I43: =I36/4 -> 0.5 | J43: 1週間の平均消化数 | P43: =P36/6 -> 0.5 | Q43: 1週間の平均消化数 | W43: =W36/6 -> 0.16666667 | X43: 1週間の平均消化数 | AD43: =AD36/6 -> 0
...

Sheet 【6月】月間進捗管理シート
A2: 縞谷 | B2: 計画値 | D2: 現状 | E2: 月 | F2: 火 | G2: 水 | H2: 木 | I2: 金 | J2: 土 | K2: 日 | L2: 月 | M2: 火 | N2: 水 | O2: 木 | P2: 金 | Q2: 土 | R2: 日 | S2: 月 | T2: 火 | U2: 水 | V2: 木 | W2: 金 | X2: 土 | Y2: 日 | Z2: 月 | AA2: 火 | AB2: 水 | AC2: 木 | AD2: 金 | AE2: 土 | AF2: 日 | AG2: 土
E3: 45810 | F3: 45811 | G3: 45812 | H3: 45813 | I3: 45814 | J3: 45815 | K3: 45816 | L3: 45817 | M3: 45818 | N3: 45819 | O3: 45820 | P3: 45821 | Q3: 45822 | R3: 45823 | S3: 45824 | T3: 45825 | U3: 45826 | V3: 45827 | W3: 45828 | X3: 45829 | Y3: 45830 | Z3: 45831 | AA3: 45832 | AB3: 45833 | AC3: 45834 | AD3: 45835 | AE3: 45836 | AF3: 45837 | AG3: 45838
A4: 売上目標 | B4: 1500000 | C4: 現状売上 | D4: =K4+R4+Y4+AF4 -> 0 | K4: =sum(E4:J4) -> 0 | R4: =sum(L4:Q4) -> 0 | Y4: =sum(S4:X4) -> 0 | AF4: =sum(Z4:AE4) -> 0
A5: 目標受注数 | B5: 7 | C5: 現状受注数 | D5: =K5+R5+Y5+AF5 -> 0 | K5: =SUM(E5:J5) -> 0 | R5: =sum(L5:Q5) -> 0 | Y5: =sum(S5:X5) -> 0 | AF5: =sum(Z5:AE5) -> 0
A6: 目標有効商談数 | B6: =B5/B9 -> 28 | C6: 現状有効商談数 | D6: =K6+R6+Y6+AF6 -> 0 | K6: =SUM(E6:J6) -> 0 | R6: =sum(L6:Q6) -> 0 | Y6: =sum(S6:X6) -> 0 | AF6: =sum(Z6:AE6) -> 0
A7: 目標アポ数 | B7: =B6/B10 -> 40 | C7: 現状無効商談数 | D7: =K7+R7+Y7+AF7 -> 0 | K7: =SUM(E7:J7) -> 0 | R7: =sum(L7:Q7) -> 0 | Y7: =sum(S7:X7) -> 0 | AF7: =sum(Z7:AE7) -> 0
A8: 目標コール数 | B8: =B7/B11 -> 2666.6667 | C8: 新規商談予定 | D8: =K8+R8+Y8+AF8 -> 0 | K8: =SUM(E8:J8) -> 0 | R8: =sum(L8:Q8) -> 0 | Y8: =sum(S8:X8) -> 0 | AF8: =sum(Z8:AE8) -> 0
A9: 目標受注率 | B9: 0.25 | C9: 当日アポ目標 | D9: =K9+R9+Y9+AF9 -> 0 | K9: =SUM(E9:J9) -> 0 | R9: =sum(L9:Q9) -> 0 | Y9: =sum(S9:X9) -> 0 | AF9: =sum(Z9:AE9) -> 0
A10: 目標出席率 | B10: 0.7 | C10: 現状アポ数 | D10: =K10+R10+Y10+AF10 -> 0 | K10: =SUM(E10:J10) -> 0 | R10: =sum(L10:Q10) -> 0 | Y10: =sum(S10:X10) -> 0 | AF10: =sum(Z10:AE10) -> 0
A11: 目標アポ転換率 | B11: 0.015 | C11: 現状コール数 | D11: =K11+R11+Y11+AF11 -> 0 | K11: =SUM(E11:J11) -> 0 | R11: =sum(L11:Q11) -> 0 | Y11: =sum(S11:X11) -> 0 | AF11: =sum(Z11:AE11) -> 0
A12: 1日の平均受注数 | B12: =D5/'【第一】案件管理シート'!E2 -> 0 | C12: 現状受注率 | D12: =D5/sum(D6:D7) -> #DIV/0! | E12: 1週間の平均受注数 | K12: =K5/6 -> 0 | L12: 1週間の平均受注数 | R12: =R5/6 -> 0 | S12: 1週間の平均受注数 | Y12: =Y5/6 -> 0 | Z12: 1週間の平均受注数 | AF12: =AF5/6 -> 0
A13: 1日の平均消化数 | B13: =D6/'【第一】案件管理シート'!E2 -> 0 | C13: 現状出席率 | D13: =sum(D6:D7)/D8 -> #DIV/0! | E13: 1週間の平均消化数 | K13: =K6/6 -> 0 | L13: 1週間の平均消化数 | R13: =R6/6 -> 0 | S13: 1週間の平均消化数 | Y13: =Y6/6 -> 0 | Z13: 1週間の平均消化数 | AF13: =AF6/6 -> 0
A14: 1日の平均アポ数 | B14: =D10/'【第一】案件管理シート'!E2 -> 0 | C14: 現状商談転換率 | D14: =SUM(D6:D7)/D10 -> #DIV/0! | E14: 1週間の平均アポ数 | K14: =K10/6 -> 0 | L14: 1週間の平均アポ数 | R14: =R10/6 -> 0 | S14: 1週間の平均アポ数 | Y14: =Y10/6 -> 0 | Z14: 1週間の平均アポ数 | AF14: =AF10/6 -> 0
A15: 1日の平均コール数 | B15: =D11/'【第一】案件管理シート'!E2 -> 0 | C15: 現状アポ転換率 | D15: =D10/D11 -> #DIV/0! | E15: 1週間の平均コール数 | K15: =K11/6 -> 0 | L15: 1週間の平均コール数 | R15: =R11/6 -> 0 | S15: 1週間の平均コール数 | Y15: =Y11/6 -> 0 | Z15: 1週間の平均コール数 | AF15: =AF11/6 -> 0
A17: 前川 | B17: 計画値 | D17: 現状 | E17: 月 | F17: 火 | G17: 水 | H17: 木 | I17: 金 | J17: 土 | K17: 日 | L17: 月 | M17: 火 | N17: 水 | O17: 木 | P17: 金 | Q17: 土 | R17: 日 | S17: 月 | T17: 火 | U17: 水 | V17: 木 | W17: 金 | X17: 土 | Y17: 日 | Z17: 月 | AA17: 火 | AB17: 水 | AC17: 木 | AD17: 金 | AE17: 土 | AF17: 日 | AG17: 土
E18: 45810 | F18: 45811 | G18: 45812 | H18: 45813 | I18: 45814 | J18: 45815 | K18: 45816 | L18: 45817 | M18: 45818 | N18: 45819 | O18: 45820 | P18: 45821 | Q18: 45822 | R18: 45823 | S18: 45824 | T18: 45825 | U18: 45826 | V18: 45827 | W18: 45828 | X18: 45829 | Y18: 45830 | Z18: 45831 | AA18: 45832 | AB18: 45833 | AC18: 45834 | AD18: 45835 | AE18: 45836 | AF18: 45837 | AG18: 45838
A19: 売上目標 | C19: 現状売上 | D19: =K19+R19+Y19+AF19 -> 0 | K19: =sum(E19:J19) -> 0 | R19: =sum(L19:Q19) -> 0 | Y19: =sum(S19:X19) -> 0 | AF19: =sum(Z19:AE19) -> 0
A20: 目標アポ数 | C20: 有効商談数 | D20: =K20+R20+Y20+AF20 -> 0 | K20: =SUM(E20:J20) -> 0 | R20: =sum(L20:Q20) -> 0 | Y20: =sum(S20:X20) -> 0 | AF20: =sum(Z20:AE20) -> 0
A21: 目標コール数 | C21: 新規商談予定 | D21: =K21+R21+Y21+AF21 -> 0 | K21: =SUM(E21:J21) -> 0 | R21: =sum(L21:Q21) -> 0 | Y21: =sum(S21:X21) -> 0 | AF21: =sum(Z21:AE21) -> 0
A22: 目標出席率 | B22: 0.7 | C22: 現状アポ数 | D22: =K22+R22+Y22+AF22 -> 2 | K22: =SUM(E22:J22) -> 0 | L22: 1 | M22: 0 | N22: 0 | O22: 1 | P22: 0 | Q22: 0 | R22: =sum(L22:Q22) -> 2 | S22: 0 | T22: 0 | Y22: =sum(S22:X22) -> 0 | AF22: =sum(Z22:AE22) -> 0
A23: 目標アポ転換率 | B23: 0.015 | C23: 現状コール数 | D23: =K23+R23+Y23+AF23 -> 624 | K23: =SUM(E23:J23) -> 0 | L23: 79 | M23: 121 | N23: 110 | O23: 58 | P23: 45 | Q23: 38 | R23: =sum(L23:Q23) -> 451 | S23: 67 | T23: 106 | Y23: =sum(S23:X23) -> 173 | AF23: =sum(Z23:AE23) -> 0
A24: 1日の平均アポ数 | B24: =D22/'【第一】案件管理シート'!E2 -> 0.13333333 | C24: 現状出席率 | D24: =D20/D21 -> #DIV/0! | E24: 1週間の平均アポ数 | K24: =K20/6 -> 0 | L24: 1週間の平均アポ数 | R24: =R20/6 -> 0 | S24: 1週間の平均アポ数 | Y24: =Y20/6 -> 0 | Z24: 1週間の平均アポ数 | AF24: =AF20/6 -> 0
A25: 1日の平均コール数 | B25: =D23/'【第一】案件管理シート'!E2 -> 41.6 | C25: 現状アポ転換率 | D25: =D22/D23 -> 0.0032051282 | E25: 1週間の平均コール数 | K25: =K21/6 -> 0 | L25: 1週間の平均コール数 | R25: =R21/6 -> 0 | S25: 1週間の平均コール数 | Y25: =Y21/6 -> 0 | Z25: 1週間の平均コール数 | AF25: =AF21/6 -> 0

Sheet 【7月】月間進捗管理シート
A2: 縞谷 | B2: 計画値 | D2: 現状 | E2: 火 | F2: 水 | G2: 木 | H2: 金 | I2: 土 | J2: 日 | K2: 月 | L2: 火 | M2: 水 | N2: 木 | O2: 金 | P2: 土 | Q2: 日 | R2: 月 | S2: 火 | T2: 水 | U2: 木 | V2: 金 | W2: 土 | X2: 日 | Y2: 月 | Z2: 火 | AA2: 水 | AB2: 木 | AC2: 金 | AD2: 土 | AE2: 日 | AF2: 月 | AG2: 火 | AH2: 水
E3: 45840 | F3: 45841 | G3: 45842 | H3: 45843 | I3: 45844 | J3: 45845 | K3: 45846 | L3: 45847 | M3: 45848 | N3: 45849 | O3: 45850 | P3: 45851 | Q3: 45852 | R3: 45853 | S3: 45854 | T3: 45855 | U3: 45856 | V3: 45857 | W3: 45858 | X3: 45859 | Y3: 45860 | Z3: 45861 | AA3: 45862 | AB3: 45863 | AC3: 45864 | AD3: 45865 | AE3: 45866 | AF3: 45867 | AG3: 45868 | AH3: 45869
A4: 売上目標 | B4: 1500000 | C4: 現状売上 | D4: =J4+Q4+X4+AE4 -> 0 | J4: =sum(E4:I4) -> 0 | Q4: =sum(K4:P4) -> 0 | X4: =sum(R4:W4) -> 0 | AE4: =sum(Y4:AD4) -> 0
A5: 目標受注数 | B5: 5 | C5: 現状受注数 | D5: =J5+Q5+X5+AE5 -> 0 | J5: =SUM(E5:I5) -> 0 | Q5: =sum(K5:P5) -> 0 | X5: =sum(R5:W5) -> 0 | AE5: =sum(Y5:AD5) -> 0
A6: 目標有効商談数 | B6: =B5/B9 -> 25 | C6: 現状有効商談数 | D6: =J6+Q6+X6+AE6 -> 0 | J6: =SUM(E6:I6) -> 0 | Q6: =sum(K6:P6) -> 0 | X6: =sum(R6:W6) -> 0 | AE6: =sum(Y6:AD6) -> 0
A7: 目標アポ数 | B7: =B6/B10 -> 41.666667 | C7: 現状無効商談数 | D7: =J7+Q7+X7+AE7 -> 0 | J7: =SUM(E7:I7) -> 0 | Q7: =sum(K7:P7) -> 0 | X7: =sum(R7:W7) -> 0 | AE7: =sum(Y7:AD7) -> 0
A8: 目標コール数 | B8: =B7/B11 -> 2777.7778 | C8: 新規商談予定 | D8: =J8+Q8+X8+AE8 -> 0 | J8: =SUM(E8:I8) -> 0 | Q8: =sum(K8:P8) -> 0 | X8: =sum(R8:W8) -> 0 | AE8: =sum(Y8:AD8) -> 0
A9: 目標受注率 | B9: 0.2 | C9: 当日アポ目標 | D9: =J9+Q9+X9+AE9 -> 0 | J9: =SUM(E9:I9) -> 0 | Q9: =sum(K9:P9) -> 0 | X9: =sum(R9:W9) -> 0 | AE9: =sum(Y9:AD9) -> 0
A10: 目標出席率 | B10: 0.6 | C10: 現状アポ数 | D10: =J10+Q10+X10+AE10 -> 0 | J10: =SUM(E10:I10) -> 0 | Q10: =sum(K10:P10) -> 0 | X10: =sum(R10:W10) -> 0 | AE10: =sum(Y10:AD10) -> 0
A11: 目標アポ転換率 | B11: 0.015 | C11: 現状コール数 | D11: =J11+Q11+X11+AE11 -> 0 | J11: =SUM(E11:I11) -> 0 | Q11: =sum(K11:P11) -> 0 | X11: =sum(R11:W11) -> 0 | AE11: =sum(Y11:AD11) -> 0
A12: 1日の平均受注数 | B12: =D5/'【第一】案件管理シート'!E2 -> 0 | C12: 現状受注率 | D12: =D5/sum(D6:D7) -> #DIV/0! | J12: =J5/6 -> 0 | K12: 1週間の平均受注数 | Q12: =Q5/6 -> 0 | R12: 1週間の平均受注数 | X12: =X5/6 -> 0 | Y12: 1週間の平均受注数 | AE12: =AE5/6 -> 0
A13: 1日の平均消化数 | B13: =D6/'【第一】案件管理シート'!E2 -> 0 | C13: 現状出席率 | D13: =sum(D6:D7)/D8 -> #DIV/0! | J13: =J6/6 -> 0 | K13: 1週間の平均消化数 | Q13: =Q6/6 -> 0 | R13: 1週間の平均消化数 | X13: =X6/6 -> 0 | Y13: 1週間の平均消化数 | AE13: =AE6/6 -> 0
A14: 1日の平均アポ数 | B14: =D10/'【第一】案件管理シート'!E2 -> 0 | C14: 現状商談転換率 | D14: =SUM(D6:D7)/D10 -> #DIV/0! | J14: =J10/6 -> 0 | K14: 1週間の平均アポ数 | Q14: =Q10/6 -> 0 | R14: 1週間の平均アポ数 | X14: =X10/6 -> 0 | Y14: 1週間の平均アポ数 | AE14: =AE10/6 -> 0
A15: 1日の平均コール数 | B15: =D11/'【第一】案件管理シート'!E2 -> 0 | C15: 現状アポ転換率 | D15: =D10/D11 -> #DIV/0! | J15: =J11/6 -> 0 | K15: 1週間の平均コール数 | Q15: =Q11/6 -> 0 | R15: 1週間の平均コール数 | X15: =X11/6 -> 0 | Y15: 1週間の平均コール数 | AE15: =AE11/6 -> 0

Sheet 【全体可視化シート】
A1: 今日の日付 | B1: =TODAY() -> 46192 | C1: 今月稼働日数 | E1: =_xlfn.NETWORKDAYS.INTL(B3, B4, "0000001", B7:B10) -> 23 | H1: 受注数 | I1: 受注率 | J1: 商談消化数 | K1: 出席率 | L1: アポ数 | M1: アポ転換率 | N1: コール数
C2: 現状稼働日数 | E2: =_xlfn.NETWORKDAYS.INTL(B3, B1, "0000001", B7:B10) -> 327 | G2: 目標 | H2: ='【5月】月間進捗管理シート'!B4 -> 14 | I2: ='【5月】月間進捗管理シート'!B8 -> 0.25 | J2: ='【5月】月間進捗管理シート'!B5 -> 56 | K2: ='【5月】月間進捗管理シート'!B9 -> 0.7 | L2: ='【5月】月間進捗管理シート'!B6 -> 80 | M2: ='【5月】月間進捗管理シート'!B10 -> 0.02 | N2: ='【5月】月間進捗管理シート'!B7 -> 4000
A3: 営業開始日 | B3: 45809 | C3: 残り稼働日数 | E3: =E1-E2+1 -> -303 | G3: 理想進捗 | H3: =H2/E1*E2 -> 199.04348 | J3: =J2/E1*E2 -> 796.17391 | L3: =L2/E1*E2 -> 1137.3913 | N3: =N2/E1*E2 -> 56869.565
A4: 営業終了日 | B4: 45838 | C4: アポ獲得日数 | E4: =_xlfn.NETWORKDAYS.INTL(B3, B5, "0000001", B7:B10) -> 17 | G4: 理想進捗率 | H4: =H3/H2 -> 14.217391 | J4: =J3/J2 -> 14.217391 | L4: =L3/L2 -> 14.217391 | N4: =N3/N2 -> 14.217391
A5: アポ獲得期限 | B5: 45829 | C5: アポ獲得期限残り日数 | E5: =E4-E2+1 -> -309 | G5: 現状 | H5: ='【5月】月間進捗管理シート'!D4 -> 120000 | I5: ='【5月】月間進捗管理シート'!D11 -> 7500 | J5: ='【5月】月間進捗管理シート'!D5 -> 16 | K5: ='【5月】月間進捗管理シート'!D12 -> 0.51612903 | L5: ='【5月】月間進捗管理シート'!D9 -> 20 | M5: ='【5月】月間進捗管理シート'!D14 -> 0.0086956522 | N5: ='【5月】月間進捗管理シート'!D10 -> 2300
A6: 商談消化期限 | B6: 45831 | C6: 消化日数 | E6: =_xlfn.NETWORKDAYS.INTL(B3, B6, "0000001", B7:B10) -> 18 | G6: 進捗率 | H6: =H5/H2 -> 8571.4286 | J6: =J5/J2 -> 0.28571429 | L6: =L5/L2 -> 0.25 | N6: =N5/N2 -> 0.575
A7: 休み | B7: 45815 | C7: 消化期限残り日数 | E7: =E6-E2+1 -> -308
B8: 45836 | C8: 受注予定 | E8: =E9+E10+E11 -> #REF! | G8: 乖離 | H8: =H5-H3 -> 119800.96 | I8: =I5-I2 -> 7499.75 | J8: =J5-J3 -> -780.17391 | K8: =K5-K2 -> -0.18387097 | L8: =L5-L3 -> -1117.3913 | M8: =M5-M2 -> -0.011304348 | N8: =N5-N3 -> -54569.565
C9: Aヨミ | E9: ='【第一】案件管理シート'!F11+'【個人案件管理シート】前川'!E9 -> 0
C10: Bヨミ | E10: ='【第一】案件管理シート'!F12+'【個人案件管理シート】前川'!E10 -> 0 | H10: 受注 | I10: 消化 | J10: アポ | K10: 架電数
C11: Cヨミ（アツイ） | E11: =#REF!+'【個人案件管理シート】前川'!E11 -> #REF! | G11: 目標 | H11: =H2 -> 14 | I11: =J2 -> 56 | J11: =L2 -> 80 | K11: =N2 -> 4000
C12: Eヨミ（残りアポ） | E12: ='【第一】案件管理シート'!F14+'【個人案件管理シート】前川'!E12 -> 0 | G12: 必要行動 | H12: =H11-E8 -> #REF! | I12: =H12/I2 -> #REF! | J12: =I12/K2-E12 -> #REF! | K12: =J12/M2 -> #REF!
D13: 45809 | E13: ='【第一】案件管理シート'!J1+'【個人案件管理シート】前川'!E13 -> 2 | G13: デイリー行動 | H13: =H12/E3 -> #REF! | I13: =I12/E7 -> #REF! | J13: =J12/E5 -> #REF! | K13: =K12/E5 -> #REF!
B14: 粗利目標
G15: 転換ループ | L15: 【週次集計用】転換ループ
B16: 現状粗利 | G16: アポ→商談 | I16: =IFERROR(__xludf.DUMMYFUNCTION("AVERAGE(FILTER(#REF!, (#REF!<>"""") * (#REF!<>""""))) "),"#REF!") -> #REF! | L16: アポ→商談 | N16: =IFERROR(__xludf.DUMMYFUNCTION("AVERAGE( FILTER( #REF!, (#REF!<>"""") * (#REF!<>"""") * ( (ROW(#REF!) <= 29) * (#REF! >= DATE(2025, 4, 14)) * (#REF! <= DATE(2025, 4, 19)) + (ROW(#REF!) > 29) ) ) ) "),"#REF!") -> #REF!
G17: アポ→受注 | I17: =IFERROR(__xludf.DUMMYFUNCTION("AVERAGE(FILTER(#REF!, (#REF!<>"""") * (#REF!<>""""))) "),"#REF!") -> #REF! | L17: アポ→受注 | N17: =IFERROR(__xludf.DUMMYFUNCTION("AVERAGE( FILTER( #REF!, (#REF!<>"""") * (#REF!<>"""") * ( (ROW(#REF!) <= 29) * (#REF! >= DATE(2025, 4, 14)) * (#REF! <= DATE(2025, 4, 19)) + (ROW(#REF!) > 29) ) ) ) "),"#REF!") -> #REF!
B18: 着地粗利(BA含)
G19: アポ→通過 | I19: =IFERROR(__xludf.DUMMYFUNCTION("AVERAGE(FILTER(#REF!, (#REF!<>"""") * (#REF!<>""""))) "),"#REF!") -> #REF! | L19: アポ→通過 | N19: =IFERROR(__xludf.DUMMYFUNCTION("AVERAGE( FILTER( #REF!, (#REF!<>"""") * (#REF!<>"""") * ( (ROW(#REF!) <= 29) * (#REF! >= DATE(2025, 4, 14)) * (#REF! <= DATE(2025, 4, 19)) + (ROW(#REF!) > 29) ) ) ) "),"#REF!") -> #REF!
B20: 平均受注粗利 | D20: =D16/E13 -> 0
G21: 商談→受注 | I21: =IFERROR(__xludf.DUMMYFUNCTION("AVERAGE(FILTER(#REF!, (#REF!<>"""") * (#REF!<>""""))) "),"#REF!") -> #REF! | L21: 商談→受注

Sheet 【8月】月間進捗管理シート
B1: 計画値 | D1: 現状 | E1: 金 | F1: 土 | G1: 日 | H1: 月 | I1: 火 | J1: 水 | K1: 木 | L1: 金 | M1: 土 | N1: 日 | O1: 月 | P1: 火 | Q1: 水 | R1: 木 | S1: 金 | T1: 土 | U1: 日 | V1: 月 | W1: 火 | X1: 水 | Y1: 木 | Z1: 金 | AA1: 土 | AB1: 日 | AC1: 月 | AD1: 火 | AE1: 水 | AF1: 木 | AG1: 金 | AH1: 土 | AI1: 日
E2: 45870 | F2: 45871 | G2: 45872 | H2: 45873 | I2: 45874 | J2: 45875 | K2: 45876 | L2: 45877 | M2: 45878 | N2: 45879 | O2: 45880 | P2: 45881 | Q2: 45882 | R2: 45883 | S2: 45884 | T2: 45885 | U2: 45886 | V2: 45887 | W2: 45888 | X2: 45889 | Y2: 45890 | Z2: 45891 | AA2: 45892 | AB2: 45893 | AC2: 45894 | AD2: 45895 | AE2: 45896 | AF2: 45897 | AG2: 45898 | AH2: 45899 | AI2: 45900
A3: 売上目標 | B3: 2200000 | C3: 現状売上 | D3: =sum(E3:M3)+sum(O3:T3)+sum(V3:AA3)+sum(AC3:AH3) -> 1615000 | N3: =sum(H3:M3) -> 0 | P3: 635000 | Q3: 235000 | R3: 235000 | U3: =sum(O3:T3) -> 1105000 | Y3: 180000 | Z3: 130000 | AB3: =sum(V3:AA3) -> 310000 | AC3: 200000 | AI3: =sum(AC3:AH3) -> 200000
A4: 目標受注数 | B4: 11 | C4: 現状受注数 | D4: =sum(E4:M4)+sum(O4:T4)+sum(V4:AA4)+sum(AC4:AH4) -> 8 | N4: =sum(H4:M4) -> 0 | P4: 3 | Q4: 1 | R4: 1 | U4: =sum(O4:T4) -> 5 | Y4: 1 | Z4: 1 | AB4: =sum(V4:AA4) -> 2 | AC4: 1 | AI4: =sum(AC4:AH4) -> 1
A5: 目標有効商談数 | B5: =B4/B8 -> 36.666667 | C5: 現状有効商談数 | D5: =sum(E5:M5)+sum(O5:T5)+sum(V5:AA5)+sum(AC5:AH5) -> 27 | F5: 1 | I5: 3 | J5: 2 | K5: 2 | L5: 2 | N5: =sum(H5:M5) -> 9 | P5: 3 | R5: 1 | U5: =sum(O5:T5) -> 4 | W5: 2 | X5: 3 | Y5: 2 | Z5: 2 | AB5: =sum(V5:AA5) -> 9 | AC5: 0 | AD5: 1 | AE5: 0 | AF5: 3 | AG5: 0 | AI5: =sum(AC5:AH5) -> 4
A6: 目標アポ数 | B6: =B5/B9 -> 56.410256 | C6: 出席率 | D6: =E6+F6+sum(H6:M6)+sum(O6:T6)+sum(V6:AA6)+sum(AC6:AH6) -> 0 | N6: =N5/N7 -> 0.81818182 | U6: =U5/U7 -> 0.8 | AB6: =AB5/AB7 -> 0.5 | AI6: =AI5/AI7 -> 0.36363636
A7: 目標コール数 | B7: =B6/B10 -> 3760.6838 | C7: 商談設定数 | D7: =sum(E7:M7)+sum(O7:T7)+sum(V7:AA7)+sum(AC7:AH7) -> 47 | E7: 0 | F7: 2 | G7: 0 | I7: 3 | J7: 2 | K7: 3 | L7: 2 | M7: 1 | N7: =sum(H7:M7) -> 11 | P7: 3 | R7: 2 | U7: =sum(O7:T7) -> 5 | W7: 4 | X7: 5 | Y7: 4 | Z7: 5 | AB7: =sum(V7:AA7) -> 18 | AC7: 3 | AD7: 2 | AE7: 1 | AF7: 3 | AG7: 2 | AI7: =sum(AC7:AH7) -> 11
A8: 目標受注率 | B8: 0.3 | C8: アポ転換率 | N8: =N9/N10 -> 0.0085348506 | U8: =U9/U10 -> 0.00089365505 | AB8: =AB9/AB10 -> 0.0083526682 | AI8: =AI9/AI10 -> 0.0067476383
A9: 目標出席率 | B9: 0.65 | C9: 現状アポ数 | D9: =sum(E9:M9)+sum(O9:T9)+sum(V9:AA9)+sum(AC9:AH9) -> 50 | E9: 4 | F9: 4 | G9: 1 | H9: 2 | I9: 1 | J9: 2 | K9: 3 | L9: 3 | M9: 1 | N9: =sum(H9:M9) -> 12 | O9: 1 | U9: =sum(O9:T9) -> 1 | V9: 3 | W9: 5 | X9: 2 | Y9: 5 | Z9: 2 | AA9: 1 | AB9: =sum(V9:AA9) -> 18 | AC9: =AC36 -> 0 | AD9: =AD36 -> 3 | AE9: =AE36 -> 2 | AF9: =AF36 -> 2 | AG9: =AG36 -> 1 | AH9: =AH36 -> 2 | AI9: =sum(AC9:AH9) -> 10
A10: 目標アポ転換率 | B10: 0.015 | C10: 現状コール数 | D10: =sum(E10:M10)+sum(O10:T10)+sum(V10:AA10)+sum(AC10:AH10) -> 6595 | E10: 141 | F10: 177 | G10: 115 | H10: 260 | I10: 204 | J10: 285 | K10: 265 | L10: 216 | M10: 176 | N10: =sum(H10:M10) -> 1406 | O10: 153 | P10: 301 | Q10: 228 | R10: 143 | T10: 294 | U10: =sum(O10:T10) -> 1119 | V10: 377 | W10: 201 | X10: 223 | Y10: 460 | Z10: 448 | AA10: 446 | AB10: =sum(V10:AA10) -> 2155 | AC10: =AC42 -> 346 | AD10: =AD42 -> 151 | AE10: =AE42 -> 63 | AF10: =AF42 -> 180 | AG10: =AG42 -> 295 | AH10: =AH42 -> 447 | AI10: =sum(AC10:AH10) -> 1482
